Workbook
Name aaa: #REF!
Name ACRound: #REF!
Name BBIE: #REF!
Name BBIE: #REF!
Name bbie2: #REF!
Name bbie2: #REF!
Name BuiltIn_AutoFilter___1: #REF!
Name BuiltIn_AutoFilter___1: #REF!
Name LineRounding: #REF!
Name RoundTotal: #REF!
Name Tax: #REF!
Name TaxableAmRound: #REF!
Name TaxAmuRound: #REF!
Name TaxRate1: #REF!
Name TaxRate2: #REF!
Name TotalRounding: #REF!
Name ｘｘｘ: #REF!
Name ｘｘｘ: #REF!
Name あ: #REF!
Name あ: #REF!
Name ああ: #REF!
Name ああ: #REF!
Name あああ: #REF!
Name あああ: #REF!
Name 改訂履歴: #REF!
Name 改訂履歴: #REF!
Name 支払通知: #REF!
Name 支払通知: #REF!
Name 支払通知３: #REF!
Name 支払通知３: #REF!
Name 請求１: #REF!
Name 請求１: #REF!
Name 単一請求: #REF!
Name 単一請求: #REF!
Name 表紙１: #REF!
Name 表紙１: #REF!

Sheet JP-PINT
A1: ID | B1: business_term | C1: business_term_ja | D1: syn_card | E1: sem_card | F1: Xpath
A2: IBG-00 | B2: Invoice | C2: デジタルインボイス | E2: 1..1 | F2: /Invoice
A3: IBT-001 | B3: Invoice number | C3: 請求書番号 | D3: 1..1 | E3: 1..1 | F3: /Invoice/cbc:ID
A4: IBT-002 | B4: Invoice issue date | C4: 請求書発行日 | D4: 1..1 | E4: 1..1 | F4: /Invoice/cbc:IssueDate
A5: IBT-168 | B5: Invoice issue time | C5: 請求書発行時刻 | D5: 0..1 | E5: 0..1 | F5: /Invoice/cbc:IssueTime
A6: IBT-003 | B6: Invoice type code | C6: 請求書タイプコード | D6: 1..1 | E6: 1..1 | F6: /Invoice/cbc:InvoiceTypeCode
A7: IBT-005 | B7: Invoice currency code | C7: 請求書通貨コード | D7: 1..1 | E7: 1..1 | F7: /Invoice/cbc:DocumentCurrencyCode
A8: IBT-006 | B8: Tax accounting currency | C8: 税会計報告用通貨コード | D8: 0..1 | E8: 0..1 | F8: /Invoice/cbc:TaxCurrencyCode
A9: IBT-007 | B9: TAX point date | C9: 課税基準日 | D9: 0..1 | E9: 0..1 | F9: /Invoice/cbc:TaxPointDate
A10: IBT-008 | B10: TAX point date code | C10: 課税基準日コード | D10: 0..1 | E10: 0..1 | F10: /Invoice/cac:InvoicePeriod/cbc:DescriptionCode
A11: IBT-009 | B11: Payment due date | C11: 支払期日 | D11: 0..1 | E11: 0..1 | F11: /Invoice/cbc:DueDate
A12: IBT-010 | B12: Buyer reference | C12: 買い手参照 | D12: 0..1 | E12: 0..1 | F12: /Invoice/cbc:BuyerReference
A13: IBT-011 | B13: Project reference | C13: プロジェクト参照 | D13: 0..1 | E13: 1..1 | F13: /Invoice/cac:ProjectReference/cbc:ID
A14: IBT-012 | B14: Contract reference | C14: 契約書参照 | D14: 0..1 | E14: 1..1 | F14: /Invoice/cac:ContractDocumentReference/cbc:ID
... A22: IBT-019 | B22: Buyer accounting reference | C22: 買い手会計参照 | D22: 0..1 | E22: 0..1 | F22: /Invoice/cbc:AccountingCost
A23: IBG-02 | B23: PROCESS CONTROL | C23: プロセスコントロール | D23: 0..1 | E23: 1..1
A24: IBT-023 | B24: Business process type | C24: ビジネスプロセスタイプ | D24: 0..1 | E24: 1..1 | F24: /Invoice/cbc:ProfileID
A25: IBT-024 | B25: Specification identifier | C25: 仕様ID | D25: 0..1 | E25: 1..1 | F25: /Invoice/cbc:CustomizationID
A26: IBG-33 | B26: INVOICE TERMS | C26: 支払条件 | D26: 0..n | E26: 0..n | F26: /Invoice/cac:PaymentTerms
A27: IBT-187 | B27: > Terms payment instructions ID | C27: 支払条件指示ID | D27: 0..1 | E27: 0..1 | F27: /Invoice/cac:PaymentTerms/cbc:PaymentMeansID
A28: IBT-020 | B28: > Payment terms | C28: 支払条件 | D28: 0..1 | E28: 0..1 | F28: /Invoice/cac:PaymentTerms/cbc:Note
A29: IBT-176 | B29: > Terms amount | C29: 支払条件金額 | D29: 0..1 | E29: 0..1 | F29: /Invoice/cac:PaymentTerms/cbc:Amount
A30: IBT-177 | B30: > Terms installment due date | C30: 分割支払支払期日 | D30: 0..1 | E30: 0..1 | F30: /Invoice/cac:PaymentTerms/cbc:InstallmentDueDate
A31: IBT-022 | B31: Invoice note | C31: 請求書注釈内容 | D31: 0..1 | E31: 0..1 | F31: /Invoice/cbc:Note
A32: IBG-03 | B32: PRECEDING INVOICE REFERENCE | C32: 先行請求書への参照 | D32: 0..n | E32: 0..n | F32: /Invoice/cac:BillingReference
A33: IBT-025 | B33: > Preceding Invoice reference | C33: 先行請求書への参照 | D33: 1..1 | E33: 1..1 | F33: /Invoice/cac:BillingReference/cac:InvoiceDocumentReference/cbc:ID
A34: IBT-026 | B34: > Preceding Invoice issue date | C34: 先行請求書発行日 | D34: 0..1 | E34: 0..1 | F34: /Invoice/cac:BillingReference/cac:InvoiceDocumentReference/cbc:IssueDate
A35: IBG-04 | B35: SELLER | C35: 売り手 | D35: 1..1 | E35: 1..1 | F35: /Invoice/cac:AccountingSupplierParty
... A39: IBT-030 | B39: > Seller legal registration identifier | C39: 売り手法人ID | D39: 0..1 | E39: 0..1 | F39: /Invoice/cac:AccountingSupplierParty/cac:Party/cac:PartyLegalEntity/cbc:CompanyID
A40: IBT-031 | B40: > Seller TAX identifier | C40: 売り手税ID | D40: 0..1 | E40: 0 | F40: /Invoice/cac:AccountingSupplierParty/cac:Party/cac:PartyTaxScheme[cac:TaxScheme/cbc:ID='VAT']/cbc:CompanyID
A41: IBT-032 | B41: > Seller TAX registration identifier | C41: 売り手税登録ID | D41: 0..1 | E41: 1..1 | F41: /Invoice/cac:AccountingSupplierParty/cac:Party/cac:PartyTaxScheme[cac:TaxScheme/cbc:ID!='VAT']/cbc:CompanyID
A42: IBT-033 | B42: > Seller additional legal information | C42: 売り手追加法的情報 | D42: 0..1 | E42: 0..1 | F42: /Invoice/cac:AccountingSupplierParty/cac:Party/cac:PartyLegalEntity/cbc:CompanyLegalForm
A43: IBT-034 | B43: > Seller electronic address | C43: 売り手電子アドレス | D43: 1..1 | E43: 1..1 | F43: /Invoice/cac:AccountingSupplierParty/cac:Party/cbc:EndpointID
A44: IBT-034-1 | B44: >>Scheme identifier | C44: スキーマID | D44: 0..1 | E44: 1..1 | F44: /Invoice/cac:AccountingSupplierParty/cac:Party/cbc:EndpointID/@scemeID
A45: IBG-05 | B45: > SELLER POSTAL ADDRESS | C45: 売り手住所 | D45: 1..1 | E45: 1..1 | F45: /Invoice/cac:AccountingSupplierParty/cac:Party/cac:PostalAddress
A46: IBT-035 | B46: >> Seller address line 1 | C46: 売り手住所欄1 | D46: 0..1 | E46: 0..1 | F46: /Invoice/cac:AccountingSupplierParty/cac:Party/cac:PostalAddress/cbc:StreetName
A47: IBT-036 | B47: >> Seller address line 2 | C47: 売り手住所欄2 | D47: 0..1 | E47: 0..1 | F47: /Invoice/cac:AccountingSupplierParty/cac:Party/cac:PostalAddress/cbc:AdditionalStreetName
A48: IBT-162 | B48: >> Seller address line 3 | C48: 売り手住所欄3 | D48: 0..1 | E48: 1..1 | F48: /Invoice/cac:AccountingSupplierParty/cac:Party/cac:PostalAddress/cac:AddressLine/cbc:Line
A49: IBT-037 | B49: >> Seller city | C49: 売り手住所 市区町村 | D49: 0..1 | E49: 0..1 | F49: /Invoice/cac:AccountingSupplierParty/cac:Party/cac:PostalAddress/cbc:CityName
A50: IBT-038 | B50: >> Seller post code | C50: 売り手郵便番号 | D50: 0..1 | E50: 0..1 | F50: /Invoice/cac:AccountingSupplierParty/cac:Party/cac:PostalAddress/cbc:PostalZone
...

Sheet 仕入明細
C1: 行番号 | D1: 鑑ヘッダ/ 明細文書ヘッダ/明細行 | E1: GR/ID | F1: 項目名 | G1: 項目定義 | H1: 繰返し | I1: 制定/ 改定 | J1: 区分３ 統合 仕入明細 | K1: 区分２ 単一 仕入明細 | L1: 区分１ コア 仕入明細 | M1: 会計連携 | N1: v1.0 （参考） | P1: ヘッダ部/明細部 | Q1: 国連CEFACT 共通辞書ID | R1: 項目種 | S1: コード表ID | T1: コード表 管理者名 | U1: コード値 入力方法 | V1: 入力値 (コード定義値を入力) | Y1: Id | Z1: BusinesTerm | AA1: Card.
A2: =IF(ISTEXT(E2),_xlfn.XLOOKUP(E2,'[1]SME09-01_LHM'!$D:$D,'[1]SME09-01_LHM'!$B:$B)) -> 1 | B2: 1 | C2: =ROW()-25 -> -23 | D2: 鑑ヘッダ | E2: IV | F2: 仕入明細書 | H2: － | I2: v4/v4.3 | P2: ヘッダ部 | R2: MA | Y2: =_xlfn.LET(_xlpm.v,_xlfn.XLOOKUP(E2,'[1]SME09-01_LHM'!$D:$D,'[1]SME09-01_LHM'!$AL:$AL),IF(_xlpm.v=0,"",_xlpm.v)) | Z2: =_xlfn.LET(_xlpm.v,IF(ISTEXT(Y2),_xlfn.XLOOKUP(Y2,'JP-PINT'!A:A,'JP-PINT'!B:B),""),IF(ISERROR(_xlpm.v),"",_xlpm.v))
A3: =IF(ISTEXT(E3),_xlfn.XLOOKUP(E3,'[1]SME09-01_LHM'!$D:$D,'[1]SME09-01_LHM'!$B:$B)) -> 2 | B3: =_xlfn.XLOOKUP(F3,'[1]SME09-01_LHM'!$I:$I,'[1]SME09-01_LHM'!$B:$B) -> 2 | C3: =ROW()-25 -> -22 | D3: 鑑ヘッダ | E3: GR1 | F3: 取引設定グループ | G3: メッセージの設定内容に関する情報からなるグループ | H3: 0..1 | I3: v1 | J3: △ | K3: △ | L3: △ | P3: ヘッダ部 | Q3: UN01005479 | R3: ASMA | Y3: =_xlfn.LET(_xlpm.v,_xlfn.XLOOKUP(E3,'[1]SME09-01_LHM'!$D:$D,'[1]SME09-01_LHM'!$AL:$AL),IF(_xlpm.v=0,"",_xlpm.v)) | Z3: =_xlfn.LET(_xlpm.v,IF(ISTEXT(Y3),_xlfn.XLOOKUP(Y3,'JP-PINT'!A:A,'JP-PINT'!B:B),""),IF(ISERROR(_xlpm.v),"",_xlpm.v))
A4: =IF(ISTEXT(E4),_xlfn.XLOOKUP(E4,'[1]SME09-01_LHM'!$D:$D,'[1]SME09-01_LHM'!$B:$B)) -> 3 | B4: =_xlfn.XLOOKUP(F4,'[1]SME09-01_LHM'!$I:$I,'[1]SME09-01_LHM'!$B:$B) -> 3 | C4: =ROW()-25 -> -21 | D4: 鑑ヘッダ | E4: ID1 | F4: 取引ID | G4: メッセージがやり取りされる取引識別番号 | H4: 0..1 | I4: v1 | J4: △ | K4: △ | L4: △ | P4: ヘッダ部 | Q4: UN01005480 | R4: BBIE | Y4: =_xlfn.LET(_xlpm.v,_xlfn.XLOOKUP(E4,'[1]SME09-01_LHM'!$D:$D,'[1]SME09-01_LHM'!$AL:$AL),IF(_xlpm.v=0,"",_xlpm.v)) | Z4: =_xlfn.LET(_xlpm.v,IF(ISTEXT(Y4),_xlfn.XLOOKUP(Y4,'JP-PINT'!A:A,'JP-PINT'!B:B),""),IF(ISERROR(_xlpm.v),"",_xlpm.v))
A5: =IF(ISTEXT(E5),_xlfn.XLOOKUP(E5,'[1]SME09-01_LHM'!$D:$D,'[1]SME09-01_LHM'!$B:$B)) -> 4 | B5: =_xlfn.XLOOKUP(F5,'[1]SME09-01_LHM'!$I:$I,'[1]SME09-01_LHM'!$B:$B) -> 4 | C5: =ROW()-25 -> -20 | D5: 鑑ヘッダ | E5: ID2 | F5: 処理日時 | G5: メッセージがやり取りされる日時 | H5: 0..1 | I5: v1/v2 | J5: △ | K5: △ | L5: △ | P5: ヘッダ部 | Q5: UN01012746 | R5: BBIE | Y5: =_xlfn.LET(_xlpm.v,_xlfn.XLOOKUP(E5,'[1]SME09-01_LHM'!$D:$D,'[1]SME09-01_LHM'!$AL:$AL),IF(_xlpm.v=0,"",_xlpm.v)) | Z5: =_xlfn.LET(_xlpm.v,IF(ISTEXT(Y5),_xlfn.XLOOKUP(Y5,'JP-PINT'!A:A,'JP-PINT'!B:B),""),IF(ISERROR(_xlpm.v),"",_xlpm.v))
A6: =IF(ISTEXT(E6),_xlfn.XLOOKUP(E6,'[1]SME09-01_LHM'!$D:$D,'[1]SME09-01_LHM'!$B:$B)) -> 5 | B6: =_xlfn.XLOOKUP(F6,'[1]SME09-01_LHM'!$I:$I,'[1]SME09-01_LHM'!$B:$B) -> 5 | C6: =ROW()-25 -> -19 | D6: 鑑ヘッダ | E6: GR2 | F6: 取引設定内容/取引プロセスグループ | G6: 取引プロセスの識別番号 共通EDIプロバイダがプロセスをセットする | H6: 1..1 | I6: v1 | J6: △ | K6: △ | L6: △ | N6: ☆ | P6: ヘッダ部 | Q6: UN01005481 | R6: ASBIE | Y6: =_xlfn.LET(_xlpm.v,_xlfn.XLOOKUP(E6,'[1]SME09-01_LHM'!$D:$D,'[1]SME09-01_LHM'!$AL:$AL),IF(_xlpm.v=0,"",_xlpm.v)) -> IBG-02 | Z6: =_xlfn.LET(_xlpm.v,IF(ISTEXT(Y6),_xlfn.XLOOKUP(Y6,'JP-PINT'!A:A,'JP-PINT'!B:B),""),IF(ISERROR(_xlpm.v),"",_xlpm.v)) -> PROCESS CONTROL | AA6: 1..1
A7: =IF(ISTEXT(E7),_xlfn.XLOOKUP(E7,'[1]SME09-01_LHM'!$D:$D,'[1]SME09-01_LHM'!$B:$B)) -> 7 | B7: =_xlfn.XLOOKUP(F7,'[1]SME09-01_LHM'!$I:$I,'[1]SME09-01_LHM'!$B:$B) -> 7 | C7: =ROW()-25 -> -18 | D7: 鑑ヘッダ | E7: ID3 | F7: 取引プロセスID | G7: 取引プロセスの識別番号 共通EDIプロバイダがプロセスをセットする | H7: 0..1 | I7: v1 | J7: △ | K7: △ | L7: △ | N7: ☆ | P7: ヘッダ部 | Q7: UN01005472 | R7: BBIE | S7: JECxxxx | T7: JEC | U7: ID値 選択入力 | Y7: =_xlfn.LET(_xlpm.v,_xlfn.XLOOKUP(E7,'[1]SME09-01_LHM'!$D:$D,'[1]SME09-01_LHM'!$AL:$AL),IF(_xlpm.v=0,"",_xlpm.v)) -> IBT-023 | Z7: =_xlfn.LET(_xlpm.v,IF(ISTEXT(Y7),_xlfn.XLOOKUP(Y7,'JP-PINT'!A:A,'JP-PINT'!B:B),""),IF(ISERROR(_xlpm.v),"",_xlpm.v)) -> Business process type | AA7: 1..1
A8: =IF(ISTEXT(E8),_xlfn.XLOOKUP(E8,'[1]SME09-01_LHM'!$D:$D,'[1]SME09-01_LHM'!$B:$B)) -> 8 | B8: =_xlfn.XLOOKUP(F8,'[1]SME09-01_LHM'!$I:$I,'[1]SME09-01_LHM'!$B:$B) -> 8 | C8: =ROW()-25 -> -17 | D8: 鑑ヘッダ | E8: ID4 | F8: 取引プロセス名 | G8: 取引プロセスの名称 | H8: 0..1 | I8: v1 | J8: △ | K8: △ | L8: △ | P8: ヘッダ部 | Q8: UN01005473 | R8: BBIE | Y8: =_xlfn.LET(_xlpm.v,_xlfn.XLOOKUP(E8,'[1]SME09-01_LHM'!$D:$D,'[1]SME09-01_LHM'!$AL:$AL),IF(_xlpm.v=0,"",_xlpm.v)) | Z8: =_xlfn.LET(_xlpm.v,IF(ISTEXT(Y8),_xlfn.XLOOKUP(Y8,'JP-PINT'!A:A,'JP-PINT'!B:B),""),IF(ISERROR(_xlpm.v),"",_xlpm.v))
A9: =IF(ISTEXT(E9),_xlfn.XLOOKUP(E9,'[1]SME09-01_LHM'!$D:$D,'[1]SME09-01_LHM'!$B:$B)) -> 11 | B9: =_xlfn.XLOOKUP(F9,'[1]SME09-01_LHM'!$I:$I,'[1]SME09-01_LHM'!$B:$B) -> 11 | C9: =ROW()-25 -> -16 | D9: 鑑ヘッダ | E9: ID5 | F9: バージョンID | G9: 取引プロセスのバージョン識別番号 | H9: 0..1 | I9: v1 | J9: △ | K9: △ | L9: △ | N9: ☆ | P9: ヘッダ部 | Q9: UN01005476 | R9: BBIE | Y9: =_xlfn.LET(_xlpm.v,_xlfn.XLOOKUP(E9,'[1]SME09-01_LHM'!$D:$D,'[1]SME09-01_LHM'!$AL:$AL),IF(_xlpm.v=0,"",_xlpm.v)) -> IBT-024 | Z9: =_xlfn.LET(_xlpm.v,IF(ISTEXT(Y9),_xlfn.XLOOKUP(Y9,'JP-PINT'!A:A,'JP-PINT'!B:B),""),IF(ISERROR(_xlpm.v),"",_xlpm.v)) -> Specification identifier | AA9: 1..1
A10: =IF(ISTEXT(E10),_xlfn.XLOOKUP(E10,'[1]SME09-01_LHM'!$D:$D,'[1]SME09-01_LHM'!$B:$B)) -> 12 | B10: =_xlfn.XLOOKUP(F10,'[1]SME09-01_LHM'!$I:$I,'[1]SME09-01_LHM'!$B:$B) -> 12 | C10: =ROW()-25 -> -15 | D10: 鑑ヘッダ | E10: ID6 | F10: バージョン発行日 | G10: 取引プロセスのバージョン発行日 | H10: 0..1 | I10: v1 | J10: △ | K10: △ | L10: △ | P10: ヘッダ部 | Q10: UN01005478 | R10: BBIE | Y10: =_xlfn.LET(_xlpm.v,_xlfn.XLOOKUP(E10,'[1]SME09-01_LHM'!$D:$D,'[1]SME09-01_LHM'!$AL:$AL),IF(_xlpm.v=0,"",_xlpm.v)) | Z10: =_xlfn.LET(_xlpm.v,IF(ISTEXT(Y10),_xlfn.XLOOKUP(Y10,'JP-PINT'!A:A,'JP-PINT'!B:B),""),IF(ISERROR(_xlpm.v),"",_xlpm.v))
A11: =IF(ISTEXT(E11),_xlfn.XLOOKUP(E11,'[1]SME09-01_LHM'!$D:$D,'[1]SME09-01_LHM'!$B:$B)) -> 13 | B11: =_xlfn.XLOOKUP(F11,'[1]SME09-01_LHM'!$I:$I,'[1]SME09-01_LHM'!$B:$B) -> 13 | C11: =ROW()-25 -> -14 | D11: 鑑ヘッダ | E11: GR3 | F11: 取引設定内容/取引シナリオグループ | G11: 取引シナリオに関する情報のグループ | H11: 0..1 | I11: v1 | J11: △ | K11: △ | L11: △ | P11: ヘッダ部 | Q11: UN01005483 | R11: ASBIE | Y11: =_xlfn.LET(_xlpm.v,_xlfn.XLOOKUP(E11,'[1]SME09-01_LHM'!$D:$D,'[1]SME09-01_LHM'!$AL:$AL),IF(_xlpm.v=0,"",_xlpm.v)) | Z11: =_xlfn.LET(_xlpm.v,IF(ISTEXT(Y11),_xlfn.XLOOKUP(Y11,'JP-PINT'!A:A,'JP-PINT'!B:B),""),IF(ISERROR(_xlpm.v),"",_xlpm.v))
A12: =IF(ISTEXT(E12),_xlfn.XLOOKUP(E12,'[1]SME09-01_LHM'!$D:$D,'[1]SME09-01_LHM'!$B:$B)) -> 15 | B12: =_xlfn.XLOOKUP(F12,'[1]SME09-01_LHM'!$I:$I,'[1]SME09-01_LHM'!$B:$B) -> 15 | C12: =ROW()-25 -> -13 | D12: 鑑ヘッダ | E12: ID7 | F12: 取引シナリオID | G12: 取引シナリオの識別番号 | H12: 0..1 | I12: v1 | J12: △ | K12: △ | L12: △ | P12: ヘッダ部 | Q12: UN01005472 | R12: BBIE | Y12: =_xlfn.LET(_xlpm.v,_xlfn.XLOOKUP(E12,'[1]SME09-01_LHM'!$D:$D,'[1]SME09-01_LHM'!$AL:$AL),IF(_xlpm.v=0,"",_xlpm.v)) | Z12: =_xlfn.LET(_xlpm.v,IF(ISTEXT(Y12),_xlfn.XLOOKUP(Y12,'JP-PINT'!A:A,'JP-PINT'!B:B),""),IF(ISERROR(_xlpm.v),"",_xlpm.v))
A13: =IF(ISTEXT(E13),_xlfn.XLOOKUP(E13,'[1]SME09-01_LHM'!$D:$D,'[1]SME09-01_LHM'!$B:$B)) -> 16 | B13: =_xlfn.XLOOKUP(F13,'[1]SME09-01_LHM'!$I:$I,'[1]SME09-01_LHM'!$B:$B) -> 16 | C13: =ROW()-25 -> -12 | D13: 鑑ヘッダ | E13: ID8 | F13: 取引シナリオ名 | G13: 取引シナリオの名称 | H13: 0..1 | I13: v1 | J13: △ | K13: △ | L13: △ | P13: ヘッダ部 | Q13: UN01005473 | R13: BBIE | Y13: =_xlfn.LET(_xlpm.v,_xlfn.XLOOKUP(E13,'[1]SME09-01_LHM'!$D:$D,'[1]SME09-01_LHM'!$AL:$AL),IF(_xlpm.v=0,"",_xlpm.v)) | Z13: =_xlfn.LET(_xlpm.v,IF(ISTEXT(Y13),_xlfn.XLOOKUP(Y13,'JP-PINT'!A:A,'JP-PINT'!B:B),""),IF(ISERROR(_xlpm.v),"",_xlpm.v))
A14: =IF(ISTEXT(E14),_xlfn.XLOOKUP(E14,'[1]SME09-01_LHM'!$D:$D,'[1]SME09-01_LHM'!$B:$B)) -> 17 | B14: =_xlfn.XLOOKUP(F14,'[1]SME09-01_LHM'!$I:$I,'[1]SME09-01_LHM'!$B:$B) -> 17 | C14: =ROW()-25 -> -11 | D14: 鑑ヘッダ | E14: GR4 | F14: 取引設定内容/アプリケーショングループ | G14: アプリケーションに関する情報のグループ | H14: 0..1 | I14: v1 | J14: △ | K14: △ | L14: △ | P14: ヘッダ部 | Q14: UN01005484 | R14: ASBIE | Y14: =_xlfn.LET(_xlpm.v,_xlfn.XLOOKUP(E14,'[1]SME09-01_LHM'!$D:$D,'[1]SME09-01_LHM'!$AL:$AL),IF(_xlpm.v=0,"",_xlpm.v)) | Z14: =_xlfn.LET(_xlpm.v,IF(ISTEXT(Y14),_xlfn.XLOOKUP(Y14,'JP-PINT'!A:A,'JP-PINT'!B:B),""),IF(ISERROR(_xlpm.v),"",_xlpm.v))
A15: =IF(ISTEXT(E15),_xlfn.XLOOKUP(E15,'[1]SME09-01_LHM'!$D:$D,'[1]SME09-01_LHM'!$B:$B)) -> 19 | B15: =_xlfn.XLOOKUP(F15,'[1]SME09-01_LHM'!$I:$I,'[1]SME09-01_LHM'!$B:$B) -> 19 | C15: =ROW()-25 -> -10 | D15: 鑑ヘッダ | E15: ID9 | F15: アプリケーションID | G15: 業務アプリケーションが実装する業界・業種識別番号 | H15: 0..1 | I15: v1 | J15: △ | K15: △ | L15: △ | P15: ヘッダ部 | Q15: UN01005472 | R15: BBIE | Y15: =_xlfn.LET(_xlpm.v,_xlfn.XLOOKUP(E15,'[1]SME09-01_LHM'!$D:$D,'[1]SME09-01_LHM'!$AL:$AL),IF(_xlpm.v=0,"",_xlpm.v)) | Z15: =_xlfn.LET(_xlpm.v,IF(ISTEXT(Y15),_xlfn.XLOOKUP(Y15,'JP-PINT'!A:A,'JP-PINT'!B:B),""),IF(ISERROR(_xlpm.v),"",_xlpm.v))
A16: =IF(ISTEXT(E16),_xlfn.XLOOKUP(E16,'[1]SME09-01_LHM'!$D:$D,'[1]SME09-01_LHM'!$B:$B)) -> 20 | B16: =_xlfn.XLOOKUP(F16,'[1]SME09-01_LHM'!$I:$I,'[1]SME09-01_LHM'!$B:$B) -> 20 | C16: =ROW()-25 -> -9 | D16: 鑑ヘッダ | E16: ID10 | F16: アプリケーション名 | G16: 業務アプリケーションが実装する業界・業種名称 | H16: 0..1 | I16: v1 | J16: △ | K16: △ | L16: △ | P16: ヘッダ部 | Q16: UN01005473 | R16: BBIE | Y16: =_xlfn.LET(_xlpm.v,_xlfn.XLOOKUP(E16,'[1]SME09-01_LHM'!$D:$D,'[1]SME09-01_LHM'!$AL:$AL),IF(_xlpm.v=0,"",_xlpm.v)) | Z16: =_xlfn.LET(_xlpm.v,IF(ISTEXT(Y16),_xlfn.XLOOKUP(Y16,'JP-PINT'!A:A,'JP-PINT'!B:B),""),IF(ISERROR(_xlpm.v),"",_xlpm.v))
A17: =IF(ISTEXT(E17),_xlfn.XLOOKUP(E17,'[1]SME09-01_LHM'!$D:$D,'[1]SME09-01_LHM'!$B:$B)) -> 21 | B17: =_xlfn.XLOOKUP(F17,'[1]SME09-01_LHM'!$I:$I,'[1]SME09-01_LHM'!$B:$B) -> 21 | C17: =ROW()-25 -> -8 | D17: 鑑ヘッダ | E17: GR5 | F17: 取引設定内容/ドメイングループ | G17: SIPSのドメインに関する情報のグループ | H17: 1..1 | I17: v1 | J17: △ | K17: △ | L17: △ | P17: ヘッダ部 | Q17: UN01005486 | R17: ASBIE | Y17: =_xlfn.LET(_xlpm.v,_xlfn.XLOOKUP(E17,'[1]SME09-01_LHM'!$D:$D,'[1]SME09-01_LHM'!$AL:$AL),IF(_xlpm.v=0,"",_xlpm.v)) | Z17: =_xlfn.LET(_xlpm.v,IF(ISTEXT(Y17),_xlfn.XLOOKUP(Y17,'JP-PINT'!A:A,'JP-PINT'!B:B),""),IF(ISERROR(_xlpm.v),"",_xlpm.v))
A18: =IF(ISTEXT(E18),_xlfn.XLOOKUP(E18,'[1]SME09-01_LHM'!$D:$D,'[1]SME09-01_LHM'!$B:$B)) -> 23 | B18: =_xlfn.XLOOKUP(F18,'[1]SME09-01_LHM'!$I:$I,'[1]SME09-01_LHM'!$B:$B) -> 23 | C18: =ROW()-25 -> -7 | D18: 鑑ヘッダ | E18: ID11 | F18: ドメインID | G18: SIPSが付与したメッセージドメイン識別番号 中小企業共通EDIドメイン＝JPSSMED | H18: 0..1 | I18: v1 | J18: △ | K18: △ | L18: △ | P18: ヘッダ部 | Q18: UN01005472 | R18: BBIE | S18: JECxxxx | T18: JEC | U18: ID値 固定入力 | V18: JPSSMED | Y18: =_xlfn.LET(_xlpm.v,_xlfn.XLOOKUP(E18,'[1]SME09-01_LHM'!$D:$D,'[1]SME09-01_LHM'!$AL:$AL),IF(_xlpm.v=0,"",_xlpm.v)) | Z18: =_xlfn.LET(_xlpm.v,IF(ISTEXT(Y18),_xlfn.XLOOKUP(Y18,'JP-PINT'!A:A,'JP-PINT'!B:B),""),IF(ISERROR(_xlpm.v),"",_xlpm.v))
A19: =IF(ISTEXT(E19),_xlfn.XLOOKUP(E19,'[1]SME09-01_LHM'!$D:$D,'[1]SME09-01_LHM'!$B:$B)) -> 24 | B19: =_xlfn.XLOOKUP(F19,'[1]SME09-01_LHM'!$I:$I,'[1]SME09-01_LHM'!$B:$B) -> 24 | C19: =ROW()-25 -> -6 | D19: 鑑ヘッダ | E19: ID12 | F19: ドメイン名 | G19: SIPSが付与したメッセージドメイン名称 | H19: 0..1 | I19: v1 | J19: △ | K19: △ | L19: △ | P19: ヘッダ部 | Q19: UN01005473 | R19: BBIE | Y19: =_xlfn.LET(_xlpm.v,_xlfn.XLOOKUP(E19,'[1]SME09-01_LHM'!$D:$D,'[1]SME09-01_LHM'!$AL:$AL),IF(_xlpm.v=0,"",_xlpm.v)) | Z19: =_xlfn.LET(_xlpm.v,IF(ISTEXT(Y19),_xlfn.XLOOKUP(Y19,'JP-PINT'!A:A,'JP-PINT'!B:B),""),IF(ISERROR(_xlpm.v),"",_xlpm.v))
A20: =IF(ISTEXT(E20),_xlfn.XLOOKUP(E20,'[1]SME09-01_LHM'!$D:$D,'[1]SME09-01_LHM'!$B:$B)) -> 27 | B20: =_xlfn.XLOOKUP(F20,'[1]SME09-01_LHM'!$I:$I,'[1]SME09-01_LHM'!$B:$B) -> 11 | C20: =ROW()-25 -> -5 | D20: 鑑ヘッダ | E20: ID13 | F20: バージョンID | G20: ドメインのバージョン識別番号 | H20: 0..1 | I20: v1 | J20: △ | K20: △ | L20: △ | P20: ヘッダ部 | Q20: UN01005476 | R20: BBIE | Y20: =_xlfn.LET(_xlpm.v,_xlfn.XLOOKUP(E20,'[1]SME09-01_LHM'!$D:$D,'[1]SME09-01_LHM'!$AL:$AL),IF(_xlpm.v=0,"",_xlpm.v)) | Z20: =_xlfn.LET(_xlpm.v,IF(ISTEXT(Y20),_xlfn.XLOOKUP(Y20,'JP-PINT'!A:A,'JP-PINT'!B:B),""),IF(ISERROR(_xlpm.v),"",_xlpm.v))
A21: =IF(ISTEXT(E21),_xlfn.XLOOKUP(E21,'[1]SME09-01_LHM'!$D:$D,'[1]SME09-01_LHM'!$B:$B)) -> 28 | B21: =_xlfn.XLOOKUP(F21,'[1]SME09-01_LHM'!$I:$I,'[1]SME09-01_LHM'!$B:$B) -> 12 | C21: =ROW()-25 -> -4 | D21: 鑑ヘッダ | E21: ID14 | F21: バージョン発行日 | G21: ドメインのバージョン発行日 | H21: 0..1 | I21: v1 | J21: △ | K21: △ | L21: △ | P21: ヘッダ部 | Q21: UN01005478 | R21: BBIE | Y21: =_xlfn.LET(_xlpm.v,_xlfn.XLOOKUP(E21,'[1]SME09-01_LHM'!$D:$D,'[1]SME09-01_LHM'!$AL:$AL),IF(_xlpm.v=0,"",_xlpm.v)) | Z21: =_xlfn.LET(_xlpm.v,IF(ISTEXT(Y21),_xlfn.XLOOKUP(Y21,'JP-PINT'!A:A,'JP-PINT'!B:B),""),IF(ISERROR(_xlpm.v),"",_xlpm.v))
A22: =IF(ISTEXT(E22),_xlfn.XLOOKUP(E22,'[1]SME09-01_LHM'!$D:$D,'[1]SME09-01_LHM'!$B:$B)) -> 29 | B22: =_xlfn.XLOOKUP(F22,'[1]SME09-01_LHM'!$I:$I,'[1]SME09-01_LHM'!$B:$B) -> 29 | C22: =ROW()-25 -> -3 | D22: 鑑ヘッダ | E22: SIGR1 | F22: インボイス文書グループ | G22: インボイス文書に関する情報項目のグループ | H22: 1..1 | I22: v1 | J22: ○ | K22: ○ | L22: ○ | P22: ヘッダ部 | Q22: UN01005861 | R22: ASMA | W22: ASMA | X22: ASMA | Y22: =_xlfn.LET(_xlpm.v,_xlfn.XLOOKUP(E22,'[1]SME09-01_LHM'!$D:$D,'[1]SME09-01_LHM'!$AL:$AL),IF(_xlpm.v=0,"",_xlpm.v)) | Z22: =_xlfn.LET(_xlpm.v,IF(ISTEXT(Y22),_xlfn.XLOOKUP(Y22,'JP-PINT'!A:A,'JP-PINT'!B:B),""),IF(ISERROR(_xlpm.v),"",_xlpm.v))
A23: =IF(ISTEXT(E23),_xlfn.XLOOKUP(E23,'[1]SME09-01_LHM'!$D:$D,'[1]SME09-01_LHM'!$B:$B)) -> 30 | B23: =_xlfn.XLOOKUP(F23,'[1]SME09-01_LHM'!$I:$I,'[1]SME09-01_LHM'!$B:$B) -> 30 | C23: =ROW()-25 -> -2 | D23: 鑑ヘッダ | E23: SIID1 | F23: インボイス文書ID | G23: インボイス文書を識別する文書ID | H23: 1..1 | I23: v1/v3 | J23: ○ | K23: ○ | L23: ○ | M23: ※ | N23: ☆ | O23: ○ | P23: ヘッダ部 | Q23: UN01005862 | R23: BBIE | W23: BBIE | X23: BBIE | Y23: =_xlfn.LET(_xlpm.v,_xlfn.XLOOKUP(E23,'[1]SME09-01_LHM'!$D:$D,'[1]SME09-01_LHM'!$AL:$AL),IF(_xlpm.v=0,"",_xlpm.v)) -> IBT-001 | Z23: =_xlfn.LET(_xlpm.v,IF(ISTEXT(Y23),_xlfn.XLOOKUP(Y23,'JP-PINT'!A:A,'JP-PINT'!B:B),""),IF(ISERROR(_xlpm.v),"",_xlpm.v)) -> Invoice number | AA23: 1..1
A24: =IF(ISTEXT(E24),_xlfn.XLOOKUP(E24,'[1]SME09-01_LHM'!$D:$D,'[1]SME09-01_LHM'!$B:$B)) -> 31 | B24: =_xlfn.XLOOKUP(F24,'[1]SME09-01_LHM'!$I:$I,'[1]SME09-01_LHM'!$B:$B) -> 31 | C24: =ROW()-25 -> -1 | D24: 鑑ヘッダ | E24: SIID2 | F24: インボイス文書名 | G24: インボイス文書の文書名称 | H24: 0..1 | I24: v1 | J24: ＊ | K24: ＊ | L24: ＊ | P24: ヘッダ部 | Q24: UN01005863 | R24: BBIE | W24: BBIE | X24: BBIE | Y24: =_xlfn.LET(_xlpm.v,_xlfn.XLOOKUP(E24,'[1]SME09-01_LHM'!$D:$D,'[1]SME09-01_LHM'!$AL:$AL),IF(_xlpm.v=0,"",_xlpm.v)) | Z24: =_xlfn.LET(_xlpm.v,IF(ISTEXT(Y24),_xlfn.XLOOKUP(Y24,'JP-PINT'!A:A,'JP-PINT'!B:B),""),IF(ISERROR(_xlpm.v),"",_xlpm.v))
A25: =IF(ISTEXT(E25),_xlfn.XLOOKUP(E25,'[1]SME09-01_LHM'!$D:$D,'[1]SME09-01_LHM'!$B:$B)) -> 32 | B25: =_xlfn.XLOOKUP(F25,'[1]SME09-01_LHM'!$I:$I,'[1]SME09-01_LHM'!$B:$B) -> 32 | C25: =ROW()-25 -> 0 | D25: 鑑ヘッダ | E25: SIID3 | F25: インボイス文書タイプコード | G25: インボイス文書のタイプを識別するコード | H25: 0..1 | I25: v1 | J25: ● | K25: ● | L25: ● | N25: ☆ | P25: ヘッダ部 | Q25: UN01005864 | R25: BBIE | S25: UNCL1001 | T25: UN/CEFACT | U25: コード値 選択入力 | W25: BBIE | X25: BBIE | Y25: =_xlfn.LET(_xlpm.v,_xlfn.XLOOKUP(E25,'[1]SME09-01_LHM'!$D:$D,'[1]SME09-01_LHM'!$AL:$AL),IF(_xlpm.v=0,"",_xlpm.v)) -> IBT-003 | Z25: =_xlfn.LET(_xlpm.v,IF(ISTEXT(Y25),_xlfn.XLOOKUP(Y25,'JP-PINT'!A:A,'JP-PINT'!B:B),""),IF(ISERROR(_xlpm.v),"",_xlpm.v)) -> Invoice type code | AA25: 1..1
A26: =IF(ISTEXT(E26),_xlfn.XLOOKUP(E26,'[1]SME09-01_LHM'!$D:$D,'[1]SME09-01_LHM'!$B:$B)) -> 33 | B26: =_xlfn.XLOOKUP(F26,'[1]SME09-01_LHM'!$I:$I,'[1]SME09-01_LHM'!$B:$B) -> 33 | C26: =ROW()-25 -> 1 | D26: 鑑ヘッダ | E26: SIID4 | F26: インボイス文書発効日 | G26: インボイス文書の発行日付，またはインボイス文書の書面上の発行日付。 | H26: 1..1 | I26: v1/v3 | J26: ○ | K26: ○ | L26: ○ | M26: ― | N26: ☆ | O26: ○ | P26: ヘッダ部 | Q26: UN01005865 | R26: BBIE | W26: BBIE | X26: BBIE | Y26: =_xlfn.LET(_xlpm.v,_xlfn.XLOOKUP(E26,'[1]SME09-01_LHM'!$D:$D,'[1]SME09-01_LHM'!$AL:$AL),IF(_xlpm.v=0,"",_xlpm.v)) -> IBT-002 | Z26: =_xlfn.LET(_xlpm.v,IF(ISTEXT(Y26),_xlfn.XLOOKUP(Y26,'JP-PINT'!A:A,'JP-PINT'!B:B),""),IF(ISERROR(_xlpm.v),"",_xlpm.v)) -> Invoice issue date | AA26: 1..1
A27: =IF(ISTEXT(E27),_xlfn.XLOOKUP(E27,'[1]SME09-01_LHM'!$D:$D,'[1]SME09-01_LHM'!$B:$B)) -> 34 | B27: =_xlfn.XLOOKUP(F27,'[1]SME09-01_LHM'!$I:$I,'[1]SME09-01_LHM'!$B:$B) -> 34 | C27: =ROW()-25 -> 2 | D27: 鑑ヘッダ | E27: IID421 | F27: インボイス文書言語ID | G27: インボイス文書の言語ID | H27: 0..1 | I27: v4.3 | J27: ● | K27: ● | L27: ● | P27: ヘッダ部 | Q27: UN01005868 | R27: BBIE | S27: 言語コード ISO639 | T27: ISO | U27: コード値 選択入力 | V27: デフォルト '=JP | W27: BBIE | X27: BBIE | Y27: =_xlfn.LET(_xlpm.v,_xlfn.XLOOKUP(E27,'[1]SME09-01_LHM'!$D:$D,'[1]SME09-01_LHM'!$AL:$AL),IF(_xlpm.v=0,"",_xlpm.v)) | Z27: =_xlfn.LET(_xlpm.v,IF(ISTEXT(Y27),_xlfn.XLOOKUP(Y27,'JP-PINT'!A:A,'JP-PINT'!B:B),""),IF(ISERROR(_xlpm.v),"",_xlpm.v))
A28: =IF(ISTEXT(E28),_xlfn.XLOOKUP(E28,'[1]SME09-01_LHM'!$D:$D,'[1]SME09-01_LHM'!$B:$B)) -> 35 | B28: =_xlfn.XLOOKUP(F28,'[1]SME09-01_LHM'!$I:$I,'[1]SME09-01_LHM'!$B:$B) -> 35 | C28: =ROW()-25 -> 3 | D28: 鑑ヘッダ | E28: SIID5 | F28: インボイス文書目的コード | G28: 発注者がインボイス文書の目的（新規、変更、取消、打切り）を管理するために付番したコード | H28: 0..1 | I28: v2 | J28: ▼ | K28: ▼ | L28: ▼ | P28: ヘッダ部 | Q28: UN01005869 | R28: BBIE | S28: UNCL1225 | T28: UN/CEFACT | U28: コード値 選択入力 | V28: デフォルト＝９（新規） | W28: BBIE | X28: BBIE | Y28: =_xlfn.LET(_xlpm.v,_xlfn.XLOOKUP(E28,'[1]SME09-01_LHM'!$D:$D,'[1]SME09-01_LHM'!$AL:$AL),IF(_xlpm.v=0,"",_xlpm.v)) | Z28: =_xlfn.LET(_xlpm.v,IF(ISTEXT(Y28),_xlfn.XLOOKUP(Y28,'JP-PINT'!A:A,'JP-PINT'!B:B),""),IF(ISERROR(_xlpm.v),"",_xlpm.v))
A29: =IF(ISTEXT(E29),_xlfn.XLOOKUP(E29,'[1]SME09-01_LHM'!$D:$D,'[1]SME09-01_LHM'!$B:$B)) -> 36 | B29: =_xlfn.XLOOKUP(F29,'[1]SME09-01_LHM'!$I:$I,'[1]SME09-01_LHM'!$B:$B) -> 36 | C29: =ROW()-25 -> 4 | D29: 鑑ヘッダ | E29: SIID6 | F29: インボイス文書履歴ID | G29: インボイス文書の変更履歴を管理するID | H29: 0..1 | I29: v4 | J29: ▼ | K29: ▼ | L29: ▼ | P29: ヘッダ部 | Q29: UN01005874 | R29: BBIE | W29: BBIE | X29: BBIE | Y29: =_xlfn.LET(_xlpm.v,_xlfn.XLOOKUP(E29,'[1]SME09-01_LHM'!$D:$D,'[1]SME09-01_LHM'!$AL:$AL),IF(_xlpm.v=0,"",_xlpm.v)) | Z29: =_xlfn.LET(_xlpm.v,IF(ISTEXT(Y29),_xlfn.XLOOKUP(Y29,'JP-PINT'!A:A,'JP-PINT'!B:B),""),IF(ISERROR(_xlpm.v),"",_xlpm.v))
A30: =IF(ISTEXT(E30),_xlfn.XLOOKUP(E30,'[1]SME09-01_LHM'!$D:$D,'[1]SME09-01_LHM'!$B:$B)) -> 37 | B30: =_xlfn.XLOOKUP(F30,'[1]SME09-01_LHM'!$I:$I,'[1]SME09-01_LHM'!$B:$B) -> 37 | C30: =ROW()-25 -> 5 | D30: 鑑ヘッダ | E30: SIID7 | F30: インボイス文書類型コード | G30: インボイス文書の類型を識別するコード | H30: 0..1 | I30: v4 | J30: ● | K30: ● | L30: ● | P30: ヘッダ部 | Q30: UN01005875 | R30: BBIE | S30: JECxxxx | T30: JEC | U30: コード値 選択入力 | W30: BBIE | X30: BBIE | Y30: =_xlfn.LET(_xlpm.v,_xlfn.XLOOKUP(E30,'[1]SME09-01_LHM'!$D:$D,'[1]SME09-01_LHM'!$AL:$AL),IF(_xlpm.v=0,"",_xlpm.v)) | Z30: =_xlfn.LET(_xlpm.v,IF(ISTEXT(Y30),_xlfn.XLOOKUP(Y30,'JP-PINT'!A:A,'JP-PINT'!B:B),""),IF(ISERROR(_xlpm.v),"",_xlpm.v))
A31: =IF(ISTEXT(E31),_xlfn.XLOOKUP(E31,'[1]SME09-01_LHM'!$D:$D,'[1]SME09-01_LHM'!$B:$B)) -> 38 | B31: =_xlfn.XLOOKUP(F31,'[1]SME09-01_LHM'!$I:$I,'[1]SME09-01_LHM'!$B:$B) -> 38 | C31: =ROW()-25 -> 6 | D31: 鑑ヘッダ | E31: SIID8 | F31: インボイス文書サブタイプコード | G31: 地域固有の文書のタイプを識別するコード | H31: 0..1 | I31: v4 | J31: ● | K31: ● | L31: ● | P31: ヘッダ部 | Q31: UN01014636 | R31: BBIE | S31: JECxxxx | T31: JEC | U31: コード値 選択入力 | V31: デフォルト＝38002 （コア仕入明細書） | W31: BBIE | X31: BBIE | Y31: =_xlfn.LET(_xlpm.v,_xlfn.XLOOKUP(E31,'[1]SME09-01_LHM'!$D:$D,'[1]SME09-01_LHM'!$AL:$AL),IF(_xlpm.v=0,"",_xlpm.v)) | Z31: =_xlfn.LET(_xlpm.v,IF(ISTEXT(Y31),_xlfn.XLOOKUP(Y31,'JP-PINT'!A:A,'JP-PINT'!B:B),""),IF(ISERROR(_xlpm.v),"",_xlpm.v))
A32: =IF(ISTEXT(E32),_xlfn.XLOOKUP(E32,'[1]SME09-01_LHM'!$D:$D,'[1]SME09-01_LHM'!$B:$B)) -> 0 | B32: =_xlfn.XLOOKUP(F32,'[1]SME09-01_LHM'!$I:$I,'[1]SME09-01_LHM'!$B:$B) -> 0 | C32: =ROW()-25 -> 7 | D32: 鑑ヘッダ | E32: SIID801 | F32: 鑑ヘッダ回答タイプコード | G32: 受注者の仕入明細回答書に対する発注者の回答に利用 鑑ヘッダ回答書の回答タイプを示すコード。 回答タイプは一括確認、部分確認、一括不可 デフォルトは一括確認 部分確認の場合は明細文書または明細行の回答タイプコードを利用して確認不可の項目を指定する | H32: 0..1 | I32: v4 | J32: ＊ | K32: ＊ | L32: ＊ | P32: ヘッダ部 | Q32: UN01015491 | R32: BBIE | S32: UNCL4343 | T32: UN/CEFACT | U32: コード値 選択入力 | V32: デフォルト＝AP （一括確認回答） | W32: BBIE | X32: BBIE | Y32: =_xlfn.LET(_xlpm.v,_xlfn.XLOOKUP(E32,'[1]SME09-01_LHM'!$D:$D,'[1]SME09-01_LHM'!$AL:$AL),IF(_xlpm.v=0,"",_xlpm.v)) | Z32: =_xlfn.LET(_xlpm.v,IF(ISTEXT(Y32),_xlfn.XLOOKUP(Y32,'JP-PINT'!A:A,'JP-PINT'!B:B),""),IF(ISERROR(_xlpm.v),"",_xlpm.v))
A33: =IF(ISTEXT(E33),_xlfn.XLOOKUP(E33,'[1]SME09-01_LHM'!$D:$D,'[1]SME09-01_LHM'!$B:$B)) -> 39 | B33: =_xlfn.XLOOKUP(F33,'[1]SME09-01_LHM'!$I:$I,'[1]SME09-01_LHM'!$B:$B) -> 39 | C33: =ROW()-25 -> 8 | D33: 鑑ヘッダ | E33: SIGR2 | F33: インボイス文書／注釈グループ | G33: インボイス文書の注釈を記述するためのグループ | H33: 0..n | I33: v1 | J33: ＊ | K33: ＊ | L33: ＊ | P33: ヘッダ部 | Q33: UN01005876 | R33: ASBIE | W33: ASBIE | X33: ASBIE | Y33: =_xlfn.LET(_xlpm.v,_xlfn.XLOOKUP(E33,'[1]SME09-01_LHM'!$D:$D,'[1]SME09-01_LHM'!$AL:$AL),IF(_xlpm.v=0,"",_xlpm.v)) | Z33: =_xlfn.LET(_xlpm.v,IF(ISTEXT(Y33),_xlfn.XLOOKUP(Y33,'JP-PINT'!A:A,'JP-PINT'!B:B),""),IF(ISERROR(_xlpm.v),"",_xlpm.v))
A34: =IF(ISTEXT(E34),_xlfn.XLOOKUP(E34,'[1]SME09-01_LHM'!$D:$D,'[1]SME09-01_LHM'!$B:$B)) -> 41 | B34: =_xlfn.XLOOKUP(F34,'[1]SME09-01_LHM'!$I:$I,'[1]SME09-01_LHM'!$B:$B) -> 41 | C34: =ROW()-25 -> 9 | D34: 鑑ヘッダ | E34: SIID9 | F34: インボイス文書注釈表題 | G34: 注釈内容の表題を示す。 | H34: 0..1 | I34: v1 | J34: ＊ | K34: ＊ | L34: ＊ | P34: ヘッダ部 | Q34: UN01005558 | R34: BBIE | W34: BBIE | X34: BBIE | Y34: =_xlfn.LET(_xlpm.v,_xlfn.XLOOKUP(E34,'[1]SME09-01_LHM'!$D:$D,'[1]SME09-01_LHM'!$AL:$AL),IF(_xlpm.v=0,"",_xlpm.v)) | Z34: =_xlfn.LET(_xlpm.v,IF(ISTEXT(Y34),_xlfn.XLOOKUP(Y34,'JP-PINT'!A:A,'JP-PINT'!B:B),""),IF(ISERROR(_xlpm.v),"",_xlpm.v))
A35: =IF(ISTEXT(E35),_xlfn.XLOOKUP(E35,'[1]SME09-01_LHM'!$D:$D,'[1]SME09-01_LHM'!$B:$B)) -> 42 | B35: =_xlfn.XLOOKUP(F35,'[1]SME09-01_LHM'!$I:$I,'[1]SME09-01_LHM'!$B:$B) -> 42 | C35: =ROW()-25 -> 10 | D35: 鑑ヘッダ | E35: SIID10 | F35: インボイス文書注釈内容 | G35: 注釈項目毎の内容情報を入力するフリースペース。 | H35: 0..1 | I35: v1 | J35: ＊ | K35: ＊ | L35: ＊ | M35: ※ | N35: ★ | P35: ヘッダ部 | Q35: UN01005560 | R35: BBIE | W35: BBIE | X35: BBIE | Y35: =_xlfn.LET(_xlpm.v,_xlfn.XLOOKUP(E35,'[1]SME09-01_LHM'!$D:$D,'[1]SME09-01_LHM'!$AL:$AL),IF(_xlpm.v=0,"",_xlpm.v)) -> IBT-022 | Z35: =_xlfn.LET(_xlpm.v,IF(ISTEXT(Y35),_xlfn.XLOOKUP(Y35,'JP-PINT'!A:A,'JP-PINT'!B:B),""),IF(ISERROR(_xlpm.v),"",_xlpm.v)) -> Invoice note | AA35: 0..1
A36: =IF(ISTEXT(E36),_xlfn.XLOOKUP(E36,'[1]SME09-01_LHM'!$D:$D,'[1]SME09-01_LHM'!$B:$B)) -> 43 | B36: =_xlfn.XLOOKUP(F36,'[1]SME09-01_LHM'!$I:$I,'[1]SME09-01_LHM'!$B:$B) -> 43 | C36: =ROW()-25 -> 11 | D36: 鑑ヘッダ | E36: SIID11 | F36: インボイス文書注釈ID | G36: 注釈の識別ID | H36: 0..1 | I36: v1 | J36: △ | K36: △ | L36: △ | P36: ヘッダ部 | Q36: UN01005562 | R36: BBIE | W36: BBIE | X36: BBIE | Y36: =_xlfn.LET(_xlpm.v,_xlfn.XLOOKUP(E36,'[1]SME09-01_LHM'!$D:$D,'[1]SME09-01_LHM'!$AL:$AL),IF(_xlpm.v=0,"",_xlpm.v)) | Z36: =_xlfn.LET(_xlpm.v,IF(ISTEXT(Y36),_xlfn.XLOOKUP(Y36,'JP-PINT'!A:A,'JP-PINT'!B:B),""),IF(ISERROR(_xlpm.v),"",_xlpm.v))
A37: =IF(ISTEXT(E37),_xlfn.XLOOKUP(E37,'[1]SME09-01_LHM'!$D:$D,'[1]SME09-01_LHM'!$B:$B)) -> 43.1 | B37: =_xlfn.XLOOKUP(F37,'[1]SME09-01_LHM'!$I:$I,'[1]SME09-01_LHM'!$B:$B) -> 43.1 | C37: =ROW()-25 -> 12 | D37: 鑑ヘッダ | E37: SIGR3 | F37: インボイス文書／参照文書グループ | G37: インボイス文書が参照する文書グループ | H37: 0..n | I37: v4 | J37: ● | K37: ● | L37: ● | N37: ★ | P37: ヘッダ部 | Q37: UN01012702 | R37: ASBIE | W37: ASBIE | X37: ASBIE | Y37: =_xlfn.LET(_xlpm.v,_xlfn.XLOOKUP(E37,'[1]SME09-01_LHM'!$D:$D,'[1]SME09-01_LHM'!$AL:$AL),IF(_xlpm.v=0,"",_xlpm.v)) -> IBG-03 | Z37: =_xlfn.LET(_xlpm.v,IF(ISTEXT(Y37),_xlfn.XLOOKUP(Y37,'JP-PINT'!A:A,'JP-PINT'!B:B),""),IF(ISERROR(_xlpm.v),"",_xlpm.v)) -> PRECEDING INVOICE REFERENCE | AA37: 0..n
A38: =IF(ISTEXT(E38),_xlfn.XLOOKUP(E38,'[1]SME09-01_LHM'!$D:$D,'[1]SME09-01_LHM'!$B:$B)) -> 43.3 | B38: =_xlfn.XLOOKUP(F38,'[1]SME09-01_LHM'!$I:$I,'[1]SME09-01_LHM'!$B:$B) -> 43.3 | C38: =ROW()-25 -> 13 | D38: 鑑ヘッダ | E38: SIID12 | F38: （鑑ヘッダ参照）文書ID | G38: インボイス文書が参照する参照文書のID | H38: 1..1 | I38: v4 | J38: ○ | K38: ○ | L38: ○ | N38: ☆ | P38: ヘッダ部 | Q38: UN01005580 | R38: BBIE | W38: BBIE | X38: BBIE | Y38: =_xlfn.LET(_xlpm.v,_xlfn.XLOOKUP(E38,'[1]SME09-01_LHM'!$D:$D,'[1]SME09-01_LHM'!$AL:$AL),IF(_xlpm.v=0,"",_xlpm.v)) -> IBT-025 | Z38: =_xlfn.LET(_xlpm.v,IF(ISTEXT(Y38),_xlfn.XLOOKUP(Y38,'JP-PINT'!A:A,'JP-PINT'!B:B),""),IF(ISERROR(_xlpm.v),"",_xlpm.v)) -> > Preceding Invoice reference | AA38: 1..1
A39: =IF(ISTEXT(E39),_xlfn.XLOOKUP(E39,'[1]SME09-01_LHM'!$D:$D,'[1]SME09-01_LHM'!$B:$B)) -> 47 | B39: =_xlfn.XLOOKUP(F39,'[1]SME09-01_LHM'!$I:$I,'[1]SME09-01_LHM'!$B:$B) -> 47 | C39: =ROW()-25 -> 14 | D39: 鑑ヘッダ | E39: SIID404 | F39: （鑑ヘッダ参照）文書URL_ID | G39: インボイス文書が参照する文書が所在するURL_ID | H39: 0..1 | I39: v4.2 | J39: ＊ | K39: ＊ | L39: ＊ | P39: ヘッダ部 | Q39: UN01005581 | R39: BBIE | W39: BBIE | X39: BBIE | Y39: =_xlfn.LET(_xlpm.v,_xlfn.XLOOKUP(E39,'[1]SME09-01_LHM'!$D:$D,'[1]SME09-01_LHM'!$AL:$AL),IF(_xlpm.v=0,"",_xlpm.v)) -> IBT-124 | Z39: =_xlfn.LET(_xlpm.v,IF(ISTEXT(Y39),_xlfn.XLOOKUP(Y39,'JP-PINT'!A:A,'JP-PINT'!B:B),""),IF(ISERROR(_xlpm.v),"",_xlpm.v)) -> > External document location | AA39: 0,,1
A40: =IF(ISTEXT(E40),_xlfn.XLOOKUP(E40,'[1]SME09-01_LHM'!$D:$D,'[1]SME09-01_LHM'!$B:$B)) -> 43.4 | B40: =_xlfn.XLOOKUP(F40,'[1]SME09-01_LHM'!$I:$I,'[1]SME09-01_LHM'!$B:$B) -> 43.4 | C40: =ROW()-25 -> 15 | D40: 鑑ヘッダ | E40: SIID13 | F40: （鑑ヘッダ参照）文書発行日 | G40: インボイス文書が参照する参照文書の発行日 | H40: 0..1 | I40: v4 | J40: ＊ | K40: ＊ | L40: ＊ | P40: ヘッダ部 | Q40: UN01005582 | R40: BBIE | W40: BBIE | X40: BBIE | Y40: =_xlfn.LET(_xlpm.v,_xlfn.XLOOKUP(E40,'[1]SME09-01_LHM'!$D:$D,'[1]SME09-01_LHM'!$AL:$AL),IF(_xlpm.v=0,"",_xlpm.v)) -> IBT-026 | Z40: =_xlfn.LET(_xlpm.v,IF(ISTEXT(Y40),_xlfn.XLOOKUP(Y40,'JP-PINT'!A:A,'JP-PINT'!B:B),""),IF(ISERROR(_xlpm.v),"",_xlpm.v)) -> > Preceding Invoice issue date
...
