Workbook

Sheet Class
A1: seq | B1: level | C1: Property type | D1: Identifier | E1: Class | F1: Property Term | G1: BaseType | H1: Associated Class | I1: Multiplicity | J1: Documentation | K1: module
A2: 1 | B2: 1 | C2: Class | E2: Communication | I2: 0..* | J2: The exchange of messages or information between parties using a specified communication channel. | K2: bus
A3: 6 | B3: 1 | C3: Class | E3: Phone | I3: 0..* | J3: Phone number information, as a specialisation of Communication. | K3: bus
A4: 12 | B4: 1 | C4: Class | E4: Fax | I4: 0..* | J4: Fax number information. | K4: bus
A5: 18 | B5: 1 | C5: Class | E5: Email | I5: 0..* | J5: Email address information. | K5: bus
A6: 24 | B6: 1 | C6: Class | E6: Web Site | I6: 0..* | J6: Web site information. | K6: bus
A7: 30 | B7: 1 | C7: Class | E7: Address | I7: 0..* | J7: Class which contains address information. | K7: bus
A8: 43 | B8: 1 | C8: Class | E8: Document Information | I8: 1..1 | J8: Parent for descriptive information about the accountingEntries Class in which it is contained. | K8: bus
A9: 61 | B9: 1 | C9: Class | E9: Contact | I9: 0..* | J9: Information about contacts. | K9: bus
A10: 74 | B10: 1 | C10: Class | E10: Accounting Method Structure | I10: 0..* | J10: Class for identifying the methods of accounting used by the entity for different reporting purposes | K10: bus
A11: 81 | B11: 1 | C11: Class | E11: Accountant | I11: 0..* | J11: Information about the relevant external accountant | K11: bus
A12: 87 | B12: 1 | C12: Class | E12: Period | I12: 0..* | J12: A tool to collect a specific set of periods used to summarize results from transactions. | K12: bus
A13: 92 | B13: 1 | C13: Class | E13: Reporting Calendar_ Period | I13: 0..* | J13: A tool to collect a specific set of periods used to summarize results from transactions. | K13: bus
... A91: 365 | B91: 1 | C91: Class | E91: Transaction_ Detail | I91: 0.* | J91: Parent class grouping transaction detail (line) level records. | K91: btx

Sheet Property
A1: seq | B1: level | C1: Property type | D1: Identifier | E1: Class | F1: Property Term | G1: BaseType | H1: Associated Class | I1: Multiplicity | J1: Documentation | K1: module
A2: 2 | B2: 2 | C2: Attribute | E2: Communication | F2: Communication URI Identifier | G2: String | I2: 0..1 | J2: The Uniform Resource Identifier (URI), such as a web or an email address, for this communication. | K2: bus
A3: 3 | B3: 2 | C3: Attribute | E3: Communication | F3: Communication Channel Code | G3: String | I3: 0..1 | J3: A code specifying the communication channel or medium through which contact information is provided or used. This code identifies the type of communication mechanism associated with a contact point, in accordance with UN/EDIFACT Data Element 3155 – Communication means type code. It enables consistent interpretation of contact details across systems and jurisdictions. Examples (non-exhaustive): TE (Telephone) Voice or data communication via a telephone network. FX (Telefax) Transmission of documents via facsimile equipment. EM (Electronic mail) Communication using electronic mail (email). AO (Uniform Resource Location : URL) Identification of the Uniform Resource Location (URL) Synonym: World wide web address. The Channel Code is used in conjunction with the corresponding communication identifier (e.g. phone number, fax number, or email address) and supports extensibility for additional communication types as defined by applicable code lists or jurisdictional requirements. | K3: bus
A4: 4 | B4: 2 | C4: Attribute | E4: Communication | F4: Communication Complete Number | G4: String | I4: 0..1 | J4: The text string of characters that make up the complete number for this communication. | K4: bus
A5: 5 | B5: 2 | C5: Attribute | E5: Communication | F5: Communication Use Code | G5: String | I5: 0..1 | J5: The code specifying the usage or purpose of this communication, such as main, investor-relations, direct. Enumerated as: bookkeeper, controller, direct, fax, investor-relations, main, switchboard, other. | K5: bus
A6: 7 | B6: 2 | C6: Specialization | E6: Phone | H6: Communication | I6: 1 | J6: Specialisation of Communication for telephone. Communication Channel Code SHALL be 'telephone'. | K6: bus
A7: 8 | B7: 2 | C7: Attribute | E7: Phone | F7: Phone URI Identifier | G7: String | I7: 0..1 | J7: The Uniform Resource Identifier (URI), such as a web or an email address, for this communication. | K7: bus
A8: 9 | B8: 2 | C8: Attribute | E8: Phone | F8: Phone Channel Code | G8: String | I8: 0..1 | J8: A code specifying the communication channel or medium through which contact information is provided or used. This code identifies the type of communication mechanism associated with a contact point, in accordance with UN/EDIFACT Data Element 3155 – Communication means type code. It enables consistent interpretation of contact details across systems and jurisdictions. Examples (non-exhaustive): TE (Telephone) Voice or data communication via a telephone network. FX (Telefax) Transmission of documents via facsimile equipment. EM (Electronic mail) Communication using electronic mail (email). The Channel Code is used in conjunction with the corresponding communication identifier (e.g. phone number, fax number, or email address) and supports extensibility for additional communication types as defined by applicable code lists or jurisdictional requirements. | K8: bus
A9: 10 | B9: 2 | C9: Attribute | E9: Phone | F9: Phone Complete Number | G9: String | I9: 0..1 | J9: The text string of characters that make up the complete number for this communication. | K9: bus
A10: 11 | B10: 2 | C10: Attribute | E10: Phone | F10: Phone Use Code | G10: String | I10: 0..1 | J10: The code specifying the usage or purpose of this communication, such as main, investor-relations, direct. Enumerated as: bookkeeper, controller, direct, fax, investor-relations, main, switchboard, other. | K10: bus
A11: 13 | B11: 2 | C11: Specialization | E11: Fax | H11: Communication | I11: 1 | J11: Specialisation of Communication for telephone. Communication Channel Code SHALL be 'telephone'. | K11: bus
A12: 14 | B12: 2 | C12: Attribute | E12: Fax | F12: Fax URI Identifier | G12: String | I12: 0..1 | J12: The Uniform Resource Identifier (URI), such as a web or an email address, for this communication. | K12: bus
A13: 15 | B13: 2 | C13: Attribute | E13: Fax | F13: Fax Channel Code | G13: String | I13: 0..1 | J13: A code specifying the communication channel or medium through which contact information is provided or used. This code identifies the type of communication mechanism associated with a contact point, in accordance with UN/EDIFACT Data Element 3155 – Communication means type code. It enables consistent interpretation of contact details across systems and jurisdictions. Examples (non-exhaustive): TE (Telephone) Voice or data communication via a telephone network. FX (Telefax) Transmission of documents via facsimile equipment. EM (Electronic mail) Communication using electronic mail (email). The Channel Code is used in conjunction with the corresponding communication identifier (e.g. phone number, fax number, or email address) and supports extensibility for additional communication types as defined by applicable code lists or jurisdictional requirements. | K13: bus
A14: 16 | B14: 2 | C14: Attribute | E14: Fax | F14: Fax Complete Number | G14: String | I14: 0..1 | J14: The text string of characters that make up the complete number for this communication. | K14: bus
A15: 17 | B15: 2 | C15: Attribute | E15: Fax | F15: Fax Use Code | G15: String | I15: 0..1 | J15: The code specifying the usage or purpose of this communication, such as main, investor-relations, direct. Enumerated as: bookkeeper, controller, direct, fax, investor-relations, main, switchboard, other. | K15: bus
A16: 19 | B16: 2 | C16: Specialization | E16: Email | H16: Communication | I16: 1 | J16: Specialisation of Communication for telephone. Communication Channel Code SHALL be 'telephone'. | K16: bus
A17: 20 | B17: 2 | C17: Attribute | E17: Email | F17: Email URI Identifier | G17: String | I17: 0..1 | J17: The Uniform Resource Identifier (URI), such as a web or an email address, for this communication. | K17: bus
A18: 21 | B18: 2 | C18: Attribute | E18: Email | F18: Email Channel Code | G18: String | I18: 0..1 | J18: A code specifying the communication channel or medium through which contact information is provided or used. This code identifies the type of communication mechanism associated with a contact point, in accordance with UN/EDIFACT Data Element 3155 – Communication means type code. It enables consistent interpretation of contact details across systems and jurisdictions. Examples (non-exhaustive): TE (Telephone) Voice or data communication via a telephone network. FX (Telefax) Transmission of documents via facsimile equipment. EM (Electronic mail) Communication using electronic mail (email). The Channel Code is used in conjunction with the corresponding communication identifier (e.g. phone number, fax number, or email address) and supports extensibility for additional communication types as defined by applicable code lists or jurisdictional requirements. | K18: bus
A19: 22 | B19: 2 | C19: Attribute | E19: Email | F19: Email Complete Number | G19: String | I19: 0..1 | J19: The text string of characters that make up the complete number for this communication. | K19: bus
A20: 23 | B20: 2 | C20: Attribute | E20: Email | F20: Email Use Code | G20: String | I20: 0..1 | J20: The code specifying the usage or purpose of this communication, such as main, investor-relations, direct. Enumerated as: bookkeeper, controller, direct, fax, investor-relations, main, switchboard, other. | K20: bus
A21: 25 | B21: 2 | C21: Specialization | E21: Web Site | H21: Communication | I21: 1 | J21: Specialisation of Communication for telephone. Communication Channel Code SHALL be 'telephone'. | K21: bus
A22: 26 | B22: 2 | C22: Attribute | E22: Web Site | F22: Web Site URI Identifier | G22: String | I22: 0..1 | J22: The Uniform Resource Identifier (URI), such as a web or an email address, for this communication. | K22: bus
A23: 27 | B23: 2 | C23: Attribute | E23: Web Site | F23: Web Site Channel Code | G23: String | I23: 0..1 | J23: A code specifying the communication channel or medium through which contact information is provided or used. This code identifies the type of communication mechanism associated with a contact point, in accordance with UN/EDIFACT Data Element 3155 – Communication means type code. It enables consistent interpretation of contact details across systems and jurisdictions. Examples (non-exhaustive): TE (Telephone) Voice or data communication via a telephone network. FX (Telefax) Transmission of documents via facsimile equipment. EM (Electronic mail) Communication using electronic mail (email). The Channel Code is used in conjunction with the corresponding communication identifier (e.g. phone number, fax number, or email address) and supports extensibility for additional communication types as defined by applicable code lists or jurisdictional requirements. | K23: bus
A24: 28 | B24: 2 | C24: Attribute | E24: Web Site | F24: Web Site Complete Number | G24: String | I24: 0..1 | J24: The text string of characters that make up the complete number for this communication. | K24: bus
A25: 29 | B25: 2 | C25: Attribute | E25: Web Site | F25: Web Site Use Code | G25: String | I25: 0..1 | J25: The code specifying the usage or purpose of this communication, such as main, investor-relations, direct. Enumerated as: bookkeeper, controller, direct, fax, investor-relations, main, switchboard, other. | K25: bus
A26: 31 | B26: 2 | C26: Attribute | E26: Address | F26: Address Name | G26: String | I26: 0..1 | J26: Address Name | K26: bus
A27: 32 | B27: 2 | C27: Attribute | E27: Address | F27: Address Description | G27: String | I27: 0..1 | J27: Address Description | K27: bus
A28: 33 | B28: 2 | C28: Attribute | E28: Address | F28: Address Purpose | G28: String | I28: 0..1 | J28: Address Purpose | K28: bus
A29: 34 | B29: 2 | C29: Attribute | E29: Address | F29: Location ID | G29: String | I29: 0..1 | J29: A code used to identify the location and to associate it with contacts and transactions | K29: bus
A30: 35 | B30: 2 | C30: Attribute | E30: Address | F30: Building Number | G30: String | I30: 0..1 | J30: Building Number | K30: bus
A31: 36 | B31: 2 | C31: Attribute | E31: Address | F31: Street | G31: String | I31: 0..1 | J31: Street address | K31: bus
A32: 37 | B32: 2 | C32: Attribute | E32: Address | F32: Address Detail | G32: String | I32: 0..1 | J32: Address Detail | K32: bus
A33: 38 | B33: 2 | C33: Attribute | E33: Address | F33: City | G33: String | I33: 0..1 | J33: City | K33: bus
... A37: 42 | B37: 2 | C37: Attribute | E37: Address | F37: Address Active Indicator | G37: Boolean | I37: 0..1 | J37: Boolean to indicate whether the address is active (="true") or inactive (="false") | K37: bus
A38: 44 | B38: 2 | C38: Attribute | D38: PK | E38: Document Information | F38: Detail Document Number | G38: String | I38: 0..1 | J38: Unique identifier for this file. | K38: bus
A39: 45 | B39: 2 | C39: Attribute | D39: PK | E39: Document Information | F39: Detail Document Type | G39: Token | I39: 1..1 | J39: account: information to fill in a chart of accounts file. balance: the results of accumulation of a complete and validated list of entries for an account (or a list of account) in a specific period - sometimes called general ledger entries: a list of individual accounting entries, which might be posted/validated or nonposted/validated journal: a self-balancing (Dr = Cr) list of entries for a specific period including beginning balance for that period. ledger: a complete list of entries for a specific account (or list of accounts) for a specific period; note - debits do not have to equal credits. assets: a listing of open receivables, payables, inventory, fixed assets or other information that can be extracted from but are not necessarily included as part of a journal entry. trialBalance: the self-balancing (Dr = Cr) result of accumulation of a complete and validated list of entries for the entity in a complete list of accounts in a specific period. taxtables: aids automated interpretation of instances that represent tax tables; Tax table are defined by using multiple [taxes] classs to gather the population of codes, authorities and rates; through [taxTableCode] cross-references in the [taxes] class, these "master file" tax tables can be referenced. mapping: a collection of mappings between interrelated data sets, such as a local and related corporate standard chart of accounts or detail data mapped to summarized end reporting concepts. versioning: a collection of changes between two versions of the same class of information, such as updates to a master file like a chart of accounts. master_file: a collection of master files, such as the customer or inventory master file. trade_documents: a collection of trade/transactional documents, such as vendor invoices or customer orders. profile_compliant: the meaning of this collection of information can be determined by understanding an established profile and especially an XBRL GL Profile. Profiles are determined through namespace declarations, schemaRef and conventions of those profiles. other: for all other types of representations. Often sorted by date or by account, these terms have specific, and sometimes different, meanings in different areas. Common practice will drive accounting method/term matches. | K39: bus
A40: 46 | B40: 2 | C40: Attribute | E40: Document Information | F40: Document Date | G40: Date Time | I40: 0..1 | J40: Date/time file was created. | K40: bus
A41: 47 | B41: 2 | C41: Attribute | E41: Document Information | F41: Revises Audit Number | G41: String | I41: 0..1 | J41: If this batch of information revises a previous batch of information, this field identifies the previous batch that is being revised. 'uniqueID' of the previous batch goes here. Developers should consider exception reporting. | K41: bus
A42: 48 | B42: 2 | C42: Attribute | E42: Document Information | F42: Action to Take with Previous Data | G42: Token | I42: 0..1 | J42: Provides guidance on action to take with previous set of data: supersedes - old data should be considered as obsolete/overwritten; supplements - belongs with that data as if it was included with it. | K42: bus
A43: 49 | B43: 2 | C43: Attribute | E43: Document Information | F43: Language | G43: QName | I43: 0..1 | J43: Primary language of the intellectual content. Where practical, the content of this field should coincide with ISO 639-1988 language codes. | K43: bus
...

Sheet FSM
A1: seq | B1: level | C1: Property type | D1: Identifier | E1: Class | F1: Property Term | G1: BaseType | H1: Associated Class | I1: Multiplicity | J1: Documentation | K1: module | L1: module
A2: 1 | B2: 1 | C2: Class | E2: Communication | I2: 0..* | J2: The exchange of messages or information between parties using a specified communication channel. | K2: bus | L2: =_xlfn.LET( _xlpm.c,C2,_xlpm.e,E2,_xlpm.f,F2,_xlpm.h,H2, IF( ISNUMBER(MATCH(_xlpm.c,{"Abstract Class","Class"},0)), _xlfn.XLOOKUP(_xlpm.e,Class!E:E,Class!K:K,""), IF(ISNUMBER(MATCH(_xlpm.c,{"Composition","Reference Association","Specialization"},0)), _xlfn.XLOOKUP(_xlpm.h,Class!E:E,Class!K:K,""), _xlfn.XLOOKUP(_xlpm.f,Property!F:F,Property!K:K,"") ) ) ) -> bus
A3: 2 | B3: 2 | C3: Attribute | E3: Communication | F3: Communication URI Identifier | G3: String | I3: 0..1 | J3: The Uniform Resource Identifier (URI), such as a web or an email address, for this communication. | K3: bus | L3: =_xlfn.LET( _xlpm.c,C3,_xlpm.e,E3,_xlpm.f,F3,_xlpm.h,H3, IF( ISNUMBER(MATCH(_xlpm.c,{"Abstract Class","Class"},0)), _xlfn.XLOOKUP(_xlpm.e,Class!E:E,Class!K:K,""), IF(ISNUMBER(MATCH(_xlpm.c,{"Composition","Reference Association","Specialization"},0)), _xlfn.XLOOKUP(_xlpm.h,Class!E:E,Class!K:K,""), _xlfn.XLOOKUP(_xlpm.f,Property!F:F,Property!K:K,"") ) ) ) -> bus
A4: 3 | B4: 2 | C4: Attribute | E4: Communication | F4: Communication Channel Code | G4: String | I4: 0..1 | J4: A code specifying the communication channel or medium through which contact information is provided or used. This code identifies the type of communication mechanism associated with a contact point, in accordance with UN/EDIFACT Data Element 3155 – Communication means type code. It enables consistent interpretation of contact details across systems and jurisdictions. Examples (non-exhaustive): TE (Telephone) Voice or data communication via a telephone network. FX (Telefax) Transmission of documents via facsimile equipment. EM (Electronic mail) Communication using electronic mail (email). AO (Uniform Resource Location : URL) Identification of the Uniform Resource Location (URL) Synonym: World wide web address. The Channel Code is used in conjunction with the corresponding communication identifier (e.g. phone number, fax number, or email address) and supports extensibility for additional communication types as defined by applicable code lists or jurisdictional requirements. | K4: bus | L4: =_xlfn.LET( _xlpm.c,C4,_xlpm.e,E4,_xlpm.f,F4,_xlpm.h,H4, IF( ISNUMBER(MATCH(_xlpm.c,{"Abstract Class","Class"},0)), _xlfn.XLOOKUP(_xlpm.e,Class!E:E,Class!K:K,""), IF(ISNUMBER(MATCH(_xlpm.c,{"Composition","Reference Association","Specialization"},0)), _xlfn.XLOOKUP(_xlpm.h,Class!E:E,Class!K:K,""), _xlfn.XLOOKUP(_xlpm.f,Property!F:F,Property!K:K,"") ) ) ) -> bus
A5: 4 | B5: 2 | C5: Attribute | E5: Communication | F5: Communication Complete Number | G5: String | I5: 0..1 | J5: The text string of characters that make up the complete number for this communication. | K5: bus | L5: =_xlfn.LET( _xlpm.c,C5,_xlpm.e,E5,_xlpm.f,F5,_xlpm.h,H5, IF( ISNUMBER(MATCH(_xlpm.c,{"Abstract Class","Class"},0)), _xlfn.XLOOKUP(_xlpm.e,Class!E:E,Class!K:K,""), IF(ISNUMBER(MATCH(_xlpm.c,{"Composition","Reference Association","Specialization"},0)), _xlfn.XLOOKUP(_xlpm.h,Class!E:E,Class!K:K,""), _xlfn.XLOOKUP(_xlpm.f,Property!F:F,Property!K:K,"") ) ) ) -> bus
A6: 5 | B6: 2 | C6: Attribute | E6: Communication | F6: Communication Use Code | G6: String | I6: 0..1 | J6: The code specifying the usage or purpose of this communication, such as main, investor-relations, direct. Enumerated as: bookkeeper, controller, direct, fax, investor-relations, main, switchboard, other. | K6: bus | L6: =_xlfn.LET( _xlpm.c,C6,_xlpm.e,E6,_xlpm.f,F6,_xlpm.h,H6, IF( ISNUMBER(MATCH(_xlpm.c,{"Abstract Class","Class"},0)), _xlfn.XLOOKUP(_xlpm.e,Class!E:E,Class!K:K,""), IF(ISNUMBER(MATCH(_xlpm.c,{"Composition","Reference Association","Specialization"},0)), _xlfn.XLOOKUP(_xlpm.h,Class!E:E,Class!K:K,""), _xlfn.XLOOKUP(_xlpm.f,Property!F:F,Property!K:K,"") ) ) ) -> bus
A7: 6 | B7: 1 | C7: Class | E7: Phone | I7: 0..* | J7: Phone number information, as a specialisation of Communication. | K7: bus | L7: =_xlfn.LET( _xlpm.c,C7,_xlpm.e,E7,_xlpm.f,F7,_xlpm.h,H7, IF( ISNUMBER(MATCH(_xlpm.c,{"Abstract Class","Class"},0)), _xlfn.XLOOKUP(_xlpm.e,Class!E:E,Class!K:K,""), IF(ISNUMBER(MATCH(_xlpm.c,{"Composition","Reference Association","Specialization"},0)), _xlfn.XLOOKUP(_xlpm.h,Class!E:E,Class!K:K,""), _xlfn.XLOOKUP(_xlpm.f,Property!F:F,Property!K:K,"") ) ) ) -> bus
A8: 7 | B8: 2 | C8: Specialization | E8: Phone | H8: Communication | I8: 1 | J8: Specialisation of Communication for telephone. Communication Channel Code SHALL be 'telephone'. | K8: bus | L8: =_xlfn.LET( _xlpm.c,C8,_xlpm.e,E8,_xlpm.f,F8,_xlpm.h,H8, IF( ISNUMBER(MATCH(_xlpm.c,{"Abstract Class","Class"},0)), _xlfn.XLOOKUP(_xlpm.e,Class!E:E,Class!K:K,""), IF(ISNUMBER(MATCH(_xlpm.c,{"Composition","Reference Association","Specialization"},0)), _xlfn.XLOOKUP(_xlpm.h,Class!E:E,Class!K:K,""), _xlfn.XLOOKUP(_xlpm.f,Property!F:F,Property!K:K,"") ) ) ) -> bus
A9: 8 | B9: 2 | C9: Attribute | E9: Phone | F9: Phone URI Identifier | G9: String | I9: 0..1 | J9: The Uniform Resource Identifier (URI), such as a web or an email address, for this communication. | K9: bus | L9: =_xlfn.LET( _xlpm.c,C9,_xlpm.e,E9,_xlpm.f,F9,_xlpm.h,H9, IF( ISNUMBER(MATCH(_xlpm.c,{"Abstract Class","Class"},0)), _xlfn.XLOOKUP(_xlpm.e,Class!E:E,Class!K:K,""), IF(ISNUMBER(MATCH(_xlpm.c,{"Composition","Reference Association","Specialization"},0)), _xlfn.XLOOKUP(_xlpm.h,Class!E:E,Class!K:K,""), _xlfn.XLOOKUP(_xlpm.f,Property!F:F,Property!K:K,"") ) ) ) -> bus
A10: 9 | B10: 2 | C10: Attribute | E10: Phone | F10: Phone Channel Code | G10: String | I10: 0..1 | J10: A code specifying the communication channel or medium through which contact information is provided or used. This code identifies the type of communication mechanism associated with a contact point, in accordance with UN/EDIFACT Data Element 3155 – Communication means type code. It enables consistent interpretation of contact details across systems and jurisdictions. Examples (non-exhaustive): TE (Telephone) Voice or data communication via a telephone network. FX (Telefax) Transmission of documents via facsimile equipment. EM (Electronic mail) Communication using electronic mail (email). The Channel Code is used in conjunction with the corresponding communication identifier (e.g. phone number, fax number, or email address) and supports extensibility for additional communication types as defined by applicable code lists or jurisdictional requirements. | K10: bus | L10: =_xlfn.LET( _xlpm.c,C10,_xlpm.e,E10,_xlpm.f,F10,_xlpm.h,H10, IF( ISNUMBER(MATCH(_xlpm.c,{"Abstract Class","Class"},0)), _xlfn.XLOOKUP(_xlpm.e,Class!E:E,Class!K:K,""), IF(ISNUMBER(MATCH(_xlpm.c,{"Composition","Reference Association","Specialization"},0)), _xlfn.XLOOKUP(_xlpm.h,Class!E:E,Class!K:K,""), _xlfn.XLOOKUP(_xlpm.f,Property!F:F,Property!K:K,"") ) ) ) -> bus
A11: 10 | B11: 2 | C11: Attribute | E11: Phone | F11: Phone Complete Number | G11: String | I11: 0..1 | J11: The text string of characters that make up the complete number for this communication. | K11: bus | L11: =_xlfn.LET( _xlpm.c,C11,_xlpm.e,E11,_xlpm.f,F11,_xlpm.h,H11, IF( ISNUMBER(MATCH(_xlpm.c,{"Abstract Class","Class"},0)), _xlfn.XLOOKUP(_xlpm.e,Class!E:E,Class!K:K,""), IF(ISNUMBER(MATCH(_xlpm.c,{"Composition","Reference Association","Specialization"},0)), _xlfn.XLOOKUP(_xlpm.h,Class!E:E,Class!K:K,""), _xlfn.XLOOKUP(_xlpm.f,Property!F:F,Property!K:K,"") ) ) ) -> bus
A12: 11 | B12: 2 | C12: Attribute | E12: Phone | F12: Phone Use Code | G12: String | I12: 0..1 | J12: The code specifying the usage or purpose of this communication, such as main, investor-relations, direct. Enumerated as: bookkeeper, controller, direct, fax, investor-relations, main, switchboard, other. | K12: bus | L12: =_xlfn.LET( _xlpm.c,C12,_xlpm.e,E12,_xlpm.f,F12,_xlpm.h,H12, IF( ISNUMBER(MATCH(_xlpm.c,{"Abstract Class","Class"},0)), _xlfn.XLOOKUP(_xlpm.e,Class!E:E,Class!K:K,""), IF(ISNUMBER(MATCH(_xlpm.c,{"Composition","Reference Association","Specialization"},0)), _xlfn.XLOOKUP(_xlpm.h,Class!E:E,Class!K:K,""), _xlfn.XLOOKUP(_xlpm.f,Property!F:F,Property!K:K,"") ) ) ) -> bus
A13: 12 | B13: 1 | C13: Class | E13: Fax | I13: 0..* | J13: Fax number information. | K13: bus | L13: =_xlfn.LET( _xlpm.c,C13,_xlpm.e,E13,_xlpm.f,F13,_xlpm.h,H13, IF( ISNUMBER(MATCH(_xlpm.c,{"Abstract Class","Class"},0)), _xlfn.XLOOKUP(_xlpm.e,Class!E:E,Class!K:K,""), IF(ISNUMBER(MATCH(_xlpm.c,{"Composition","Reference Association","Specialization"},0)), _xlfn.XLOOKUP(_xlpm.h,Class!E:E,Class!K:K,""), _xlfn.XLOOKUP(_xlpm.f,Property!F:F,Property!K:K,"") ) ) ) -> bus
A14: 13 | B14: 2 | C14: Specialization | E14: Fax | H14: Communication | I14: 1 | J14: Specialisation of Communication for telephone. Communication Channel Code SHALL be 'telephone'. | K14: bus | L14: =_xlfn.LET( _xlpm.c,C14,_xlpm.e,E14,_xlpm.f,F14,_xlpm.h,H14, IF( ISNUMBER(MATCH(_xlpm.c,{"Abstract Class","Class"},0)), _xlfn.XLOOKUP(_xlpm.e,Class!E:E,Class!K:K,""), IF(ISNUMBER(MATCH(_xlpm.c,{"Composition","Reference Association","Specialization"},0)), _xlfn.XLOOKUP(_xlpm.h,Class!E:E,Class!K:K,""), _xlfn.XLOOKUP(_xlpm.f,Property!F:F,Property!K:K,"") ) ) ) -> bus
A15: 14 | B15: 2 | C15: Attribute | E15: Fax | F15: Fax URI Identifier | G15: String | I15: 0..1 | J15: The Uniform Resource Identifier (URI), such as a web or an email address, for this communication. | K15: bus | L15: =_xlfn.LET( _xlpm.c,C15,_xlpm.e,E15,_xlpm.f,F15,_xlpm.h,H15, IF( ISNUMBER(MATCH(_xlpm.c,{"Abstract Class","Class"},0)), _xlfn.XLOOKUP(_xlpm.e,Class!E:E,Class!K:K,""), IF(ISNUMBER(MATCH(_xlpm.c,{"Composition","Reference Association","Specialization"},0)), _xlfn.XLOOKUP(_xlpm.h,Class!E:E,Class!K:K,""), _xlfn.XLOOKUP(_xlpm.f,Property!F:F,Property!K:K,"") ) ) ) -> bus
A16: 15 | B16: 2 | C16: Attribute | E16: Fax | F16: Fax Channel Code | G16: String | I16: 0..1 | J16: A code specifying the communication channel or medium through which contact information is provided or used. This code identifies the type of communication mechanism associated with a contact point, in accordance with UN/EDIFACT Data Element 3155 – Communication means type code. It enables consistent interpretation of contact details across systems and jurisdictions. Examples (non-exhaustive): TE (Telephone) Voice or data communication via a telephone network. FX (Telefax) Transmission of documents via facsimile equipment. EM (Electronic mail) Communication using electronic mail (email). The Channel Code is used in conjunction with the corresponding communication identifier (e.g. phone number, fax number, or email address) and supports extensibility for additional communication types as defined by applicable code lists or jurisdictional requirements. | K16: bus | L16: =_xlfn.LET( _xlpm.c,C16,_xlpm.e,E16,_xlpm.f,F16,_xlpm.h,H16, IF( ISNUMBER(MATCH(_xlpm.c,{"Abstract Class","Class"},0)), _xlfn.XLOOKUP(_xlpm.e,Class!E:E,Class!K:K,""), IF(ISNUMBER(MATCH(_xlpm.c,{"Composition","Reference Association","Specialization"},0)), _xlfn.XLOOKUP(_xlpm.h,Class!E:E,Class!K:K,""), _xlfn.XLOOKUP(_xlpm.f,Property!F:F,Property!K:K,"") ) ) ) -> bus
A17: 16 | B17: 2 | C17: Attribute | E17: Fax | F17: Fax Complete Number | G17: String | I17: 0..1 | J17: The text string of characters that make up the complete number for this communication. | K17: bus | L17: =_xlfn.LET( _xlpm.c,C17,_xlpm.e,E17,_xlpm.f,F17,_xlpm.h,H17, IF( ISNUMBER(MATCH(_xlpm.c,{"Abstract Class","Class"},0)), _xlfn.XLOOKUP(_xlpm.e,Class!E:E,Class!K:K,""), IF(ISNUMBER(MATCH(_xlpm.c,{"Composition","Reference Association","Specialization"},0)), _xlfn.XLOOKUP(_xlpm.h,Class!E:E,Class!K:K,""), _xlfn.XLOOKUP(_xlpm.f,Property!F:F,Property!K:K,"") ) ) ) -> bus
A18: 17 | B18: 2 | C18: Attribute | E18: Fax | F18: Fax Use Code | G18: String | I18: 0..1 | J18: The code specifying the usage or purpose of this communication, such as main, investor-relations, direct. Enumerated as: bookkeeper, controller, direct, fax, investor-relations, main, switchboard, other. | K18: bus | L18: =_xlfn.LET( _xlpm.c,C18,_xlpm.e,E18,_xlpm.f,F18,_xlpm.h,H18, IF( ISNUMBER(MATCH(_xlpm.c,{"Abstract Class","Class"},0)), _xlfn.XLOOKUP(_xlpm.e,Class!E:E,Class!K:K,""), IF(ISNUMBER(MATCH(_xlpm.c,{"Composition","Reference Association","Specialization"},0)), _xlfn.XLOOKUP(_xlpm.h,Class!E:E,Class!K:K,""), _xlfn.XLOOKUP(_xlpm.f,Property!F:F,Property!K:K,"") ) ) ) -> bus
A19: 18 | B19: 1 | C19: Class | E19: Email | I19: 0..* | J19: Email address information. | K19: bus | L19: =_xlfn.LET( _xlpm.c,C19,_xlpm.e,E19,_xlpm.f,F19,_xlpm.h,H19, IF( ISNUMBER(MATCH(_xlpm.c,{"Abstract Class","Class"},0)), _xlfn.XLOOKUP(_xlpm.e,Class!E:E,Class!K:K,""), IF(ISNUMBER(MATCH(_xlpm.c,{"Composition","Reference Association","Specialization"},0)), _xlfn.XLOOKUP(_xlpm.h,Class!E:E,Class!K:K,""), _xlfn.XLOOKUP(_xlpm.f,Property!F:F,Property!K:K,"") ) ) ) -> bus
A20: 19 | B20: 2 | C20: Specialization | E20: Email | H20: Communication | I20: 1 | J20: Specialisation of Communication for telephone. Communication Channel Code SHALL be 'telephone'. | K20: bus | L20: =_xlfn.LET( _xlpm.c,C20,_xlpm.e,E20,_xlpm.f,F20,_xlpm.h,H20, IF( ISNUMBER(MATCH(_xlpm.c,{"Abstract Class","Class"},0)), _xlfn.XLOOKUP(_xlpm.e,Class!E:E,Class!K:K,""), IF(ISNUMBER(MATCH(_xlpm.c,{"Composition","Reference Association","Specialization"},0)), _xlfn.XLOOKUP(_xlpm.h,Class!E:E,Class!K:K,""), _xlfn.XLOOKUP(_xlpm.f,Property!F:F,Property!K:K,"") ) ) ) -> bus
A21: 20 | B21: 2 | C21: Attribute | E21: Email | F21: Email URI Identifier | G21: String | I21: 0..1 | J21: The Uniform Resource Identifier (URI), such as a web or an email address, for this communication. | K21: bus | L21: =_xlfn.LET( _xlpm.c,C21,_xlpm.e,E21,_xlpm.f,F21,_xlpm.h,H21, IF( ISNUMBER(MATCH(_xlpm.c,{"Abstract Class","Class"},0)), _xlfn.XLOOKUP(_xlpm.e,Class!E:E,Class!K:K,""), IF(ISNUMBER(MATCH(_xlpm.c,{"Composition","Reference Association","Specialization"},0)), _xlfn.XLOOKUP(_xlpm.h,Class!E:E,Class!K:K,""), _xlfn.XLOOKUP(_xlpm.f,Property!F:F,Property!K:K,"") ) ) ) -> bus
A22: 21 | B22: 2 | C22: Attribute | E22: Email | F22: Email Channel Code | G22: String | I22: 0..1 | J22: A code specifying the communication channel or medium through which contact information is provided or used. This code identifies the type of communication mechanism associated with a contact point, in accordance with UN/EDIFACT Data Element 3155 – Communication means type code. It enables consistent interpretation of contact details across systems and jurisdictions. Examples (non-exhaustive): TE (Telephone) Voice or data communication via a telephone network. FX (Telefax) Transmission of documents via facsimile equipment. EM (Electronic mail) Communication using electronic mail (email). The Channel Code is used in conjunction with the corresponding communication identifier (e.g. phone number, fax number, or email address) and supports extensibility for additional communication types as defined by applicable code lists or jurisdictional requirements. | K22: bus | L22: =_xlfn.LET( _xlpm.c,C22,_xlpm.e,E22,_xlpm.f,F22,_xlpm.h,H22, IF( ISNUMBER(MATCH(_xlpm.c,{"Abstract Class","Class"},0)), _xlfn.XLOOKUP(_xlpm.e,Class!E:E,Class!K:K,""), IF(ISNUMBER(MATCH(_xlpm.c,{"Composition","Reference Association","Specialization"},0)), _xlfn.XLOOKUP(_xlpm.h,Class!E:E,Class!K:K,""), _xlfn.XLOOKUP(_xlpm.f,Property!F:F,Property!K:K,"") ) ) ) -> bus
A23: 22 | B23: 2 | C23: Attribute | E23: Email | F23: Email Complete Number | G23: String | I23: 0..1 | J23: The text string of characters that make up the complete number for this communication. | K23: bus | L23: =_xlfn.LET( _xlpm.c,C23,_xlpm.e,E23,_xlpm.f,F23,_xlpm.h,H23, IF( ISNUMBER(MATCH(_xlpm.c,{"Abstract Class","Class"},0)), _xlfn.XLOOKUP(_xlpm.e,Class!E:E,Class!K:K,""), IF(ISNUMBER(MATCH(_xlpm.c,{"Composition","Reference Association","Specialization"},0)), _xlfn.XLOOKUP(_xlpm.h,Class!E:E,Class!K:K,""), _xlfn.XLOOKUP(_xlpm.f,Property!F:F,Property!K:K,"") ) ) ) -> bus
A24: 23 | B24: 2 | C24: Attribute | E24: Email | F24: Email Use Code | G24: String | I24: 0..1 | J24: The code specifying the usage or purpose of this communication, such as main, investor-relations, direct. Enumerated as: bookkeeper, controller, direct, fax, investor-relations, main, switchboard, other. | K24: bus | L24: =_xlfn.LET( _xlpm.c,C24,_xlpm.e,E24,_xlpm.f,F24,_xlpm.h,H24, IF( ISNUMBER(MATCH(_xlpm.c,{"Abstract Class","Class"},0)), _xlfn.XLOOKUP(_xlpm.e,Class!E:E,Class!K:K,""), IF(ISNUMBER(MATCH(_xlpm.c,{"Composition","Reference Association","Specialization"},0)), _xlfn.XLOOKUP(_xlpm.h,Class!E:E,Class!K:K,""), _xlfn.XLOOKUP(_xlpm.f,Property!F:F,Property!K:K,"") ) ) ) -> bus
A25: 24 | B25: 1 | C25: Class | E25: Web Site | I25: 0..* | J25: Web site information. | K25: bus | L25: =_xlfn.LET( _xlpm.c,C25,_xlpm.e,E25,_xlpm.f,F25,_xlpm.h,H25, IF( ISNUMBER(MATCH(_xlpm.c,{"Abstract Class","Class"},0)), _xlfn.XLOOKUP(_xlpm.e,Class!E:E,Class!K:K,""), IF(ISNUMBER(MATCH(_xlpm.c,{"Composition","Reference Association","Specialization"},0)), _xlfn.XLOOKUP(_xlpm.h,Class!E:E,Class!K:K,""), _xlfn.XLOOKUP(_xlpm.f,Property!F:F,Property!K:K,"") ) ) ) -> bus
A26: 25 | B26: 2 | C26: Specialization | E26: Web Site | H26: Communication | I26: 1 | J26: Specialisation of Communication for telephone. Communication Channel Code SHALL be 'telephone'. | K26: bus | L26: =_xlfn.LET( _xlpm.c,C26,_xlpm.e,E26,_xlpm.f,F26,_xlpm.h,H26, IF( ISNUMBER(MATCH(_xlpm.c,{"Abstract Class","Class"},0)), _xlfn.XLOOKUP(_xlpm.e,Class!E:E,Class!K:K,""), IF(ISNUMBER(MATCH(_xlpm.c,{"Composition","Reference Association","Specialization"},0)), _xlfn.XLOOKUP(_xlpm.h,Class!E:E,Class!K:K,""), _xlfn.XLOOKUP(_xlpm.f,Property!F:F,Property!K:K,"") ) ) ) -> bus
A27: 26 | B27: 2 | C27: Attribute | E27: Web Site | F27: Web Site URI Identifier | G27: String | I27: 0..1 | J27: The Uniform Resource Identifier (URI), such as a web or an email address, for this communication. | K27: bus | L27: =_xlfn.LET( _xlpm.c,C27,_xlpm.e,E27,_xlpm.f,F27,_xlpm.h,H27, IF( ISNUMBER(MATCH(_xlpm.c,{"Abstract Class","Class"},0)), _xlfn.XLOOKUP(_xlpm.e,Class!E:E,Class!K:K,""), IF(ISNUMBER(MATCH(_xlpm.c,{"Composition","Reference Association","Specialization"},0)), _xlfn.XLOOKUP(_xlpm.h,Class!E:E,Class!K:K,""), _xlfn.XLOOKUP(_xlpm.f,Property!F:F,Property!K:K,"") ) ) ) -> bus
A28: 27 | B28: 2 | C28: Attribute | E28: Web Site | F28: Web Site Channel Code | G28: String | I28: 0..1 | J28: A code specifying the communication channel or medium through which contact information is provided or used. This code identifies the type of communication mechanism associated with a contact point, in accordance with UN/EDIFACT Data Element 3155 – Communication means type code. It enables consistent interpretation of contact details across systems and jurisdictions. Examples (non-exhaustive): TE (Telephone) Voice or data communication via a telephone network. FX (Telefax) Transmission of documents via facsimile equipment. EM (Electronic mail) Communication using electronic mail (email). The Channel Code is used in conjunction with the corresponding communication identifier (e.g. phone number, fax number, or email address) and supports extensibility for additional communication types as defined by applicable code lists or jurisdictional requirements. | K28: bus | L28: =_xlfn.LET( _xlpm.c,C28,_xlpm.e,E28,_xlpm.f,F28,_xlpm.h,H28, IF( ISNUMBER(MATCH(_xlpm.c,{"Abstract Class","Class"},0)), _xlfn.XLOOKUP(_xlpm.e,Class!E:E,Class!K:K,""), IF(ISNUMBER(MATCH(_xlpm.c,{"Composition","Reference Association","Specialization"},0)), _xlfn.XLOOKUP(_xlpm.h,Class!E:E,Class!K:K,""), _xlfn.XLOOKUP(_xlpm.f,Property!F:F,Property!K:K,"") ) ) ) -> bus
A29: 28 | B29: 2 | C29: Attribute | E29: Web Site | F29: Web Site Complete Number | G29: String | I29: 0..1 | J29: The text string of characters that make up the complete number for this communication. | K29: bus | L29: =_xlfn.LET( _xlpm.c,C29,_xlpm.e,E29,_xlpm.f,F29,_xlpm.h,H29, IF( ISNUMBER(MATCH(_xlpm.c,{"Abstract Class","Class"},0)), _xlfn.XLOOKUP(_xlpm.e,Class!E:E,Class!K:K,""), IF(ISNUMBER(MATCH(_xlpm.c,{"Composition","Reference Association","Specialization"},0)), _xlfn.XLOOKUP(_xlpm.h,Class!E:E,Class!K:K,""), _xlfn.XLOOKUP(_xlpm.f,Property!F:F,Property!K:K,"") ) ) ) -> bus
A30: 29 | B30: 2 | C30: Attribute | E30: Web Site | F30: Web Site Use Code | G30: String | I30: 0..1 | J30: The code specifying the usage or purpose of this communication, such as main, investor-relations, direct. Enumerated as: bookkeeper, controller, direct, fax, investor-relations, main, switchboard, other. | K30: bus | L30: =_xlfn.LET( _xlpm.c,C30,_xlpm.e,E30,_xlpm.f,F30,_xlpm.h,H30, IF( ISNUMBER(MATCH(_xlpm.c,{"Abstract Class","Class"},0)), _xlfn.XLOOKUP(_xlpm.e,Class!E:E,Class!K:K,""), IF(ISNUMBER(MATCH(_xlpm.c,{"Composition","Reference Association","Specialization"},0)), _xlfn.XLOOKUP(_xlpm.h,Class!E:E,Class!K:K,""), _xlfn.XLOOKUP(_xlpm.f,Property!F:F,Property!K:K,"") ) ) ) -> bus
A31: 30 | B31: 1 | C31: Class | E31: Address | I31: 0..* | J31: Class which contains address information. | K31: bus | L31: =_xlfn.LET( _xlpm.c,C31,_xlpm.e,E31,_xlpm.f,F31,_xlpm.h,H31, IF( ISNUMBER(MATCH(_xlpm.c,{"Abstract Class","Class"},0)), _xlfn.XLOOKUP(_xlpm.e,Class!E:E,Class!K:K,""), IF(ISNUMBER(MATCH(_xlpm.c,{"Composition","Reference Association","Specialization"},0)), _xlfn.XLOOKUP(_xlpm.h,Class!E:E,Class!K:K,""), _xlfn.XLOOKUP(_xlpm.f,Property!F:F,Property!K:K,"") ) ) ) -> bus
A32: 31 | B32: 2 | C32: Attribute | E32: Address | F32: Address Name | G32: String | I32: 0..1 | J32: Address Name | K32: bus | L32: =_xlfn.LET( _xlpm.c,C32,_xlpm.e,E32,_xlpm.f,F32,_xlpm.h,H32, IF( ISNUMBER(MATCH(_xlpm.c,{"Abstract Class","Class"},0)), _xlfn.XLOOKUP(_xlpm.e,Class!E:E,Class!K:K,""), IF(ISNUMBER(MATCH(_xlpm.c,{"Composition","Reference Association","Specialization"},0)), _xlfn.XLOOKUP(_xlpm.h,Class!E:E,Class!K:K,""), _xlfn.XLOOKUP(_xlpm.f,Property!F:F,Property!K:K,"") ) ) ) -> bus
A33: 32 | B33: 2 | C33: Attribute | E33: Address | F33: Address Description | G33: String | I33: 0..1 | J33: Address Description | K33: bus | L33: =_xlfn.LET( _xlpm.c,C33,_xlpm.e,E33,_xlpm.f,F33,_xlpm.h,H33, IF( ISNUMBER(MATCH(_xlpm.c,{"Abstract Class","Class"},0)), _xlfn.XLOOKUP(_xlpm.e,Class!E:E,Class!K:K,""), IF(ISNUMBER(MATCH(_xlpm.c,{"Composition","Reference Association","Specialization"},0)), _xlfn.XLOOKUP(_xlpm.h,Class!E:E,Class!K:K,""), _xlfn.XLOOKUP(_xlpm.f,Property!F:F,Property!K:K,"") ) ) ) -> bus
A34: 33 | B34: 2 | C34: Attribute | E34: Address | F34: Address Purpose | G34: String | I34: 0..1 | J34: Address Purpose | K34: bus | L34: =_xlfn.LET( _xlpm.c,C34,_xlpm.e,E34,_xlpm.f,F34,_xlpm.h,H34, IF( ISNUMBER(MATCH(_xlpm.c,{"Abstract Class","Class"},0)), _xlfn.XLOOKUP(_xlpm.e,Class!E:E,Class!K:K,""), IF(ISNUMBER(MATCH(_xlpm.c,{"Composition","Reference Association","Specialization"},0)), _xlfn.XLOOKUP(_xlpm.h,Class!E:E,Class!K:K,""), _xlfn.XLOOKUP(_xlpm.f,Property!F:F,Property!K:K,"") ) ) ) -> bus
A35: 34 | B35: 2 | C35: Attribute | E35: Address | F35: Location ID | G35: String | I35: 0..1 | J35: A code used to identify the location and to associate it with contacts and transactions | K35: bus | L35: =_xlfn.LET( _xlpm.c,C35,_xlpm.e,E35,_xlpm.f,F35,_xlpm.h,H35, IF( ISNUMBER(MATCH(_xlpm.c,{"Abstract Class","Class"},0)), _xlfn.XLOOKUP(_xlpm.e,Class!E:E,Class!K:K,""), IF(ISNUMBER(MATCH(_xlpm.c,{"Composition","Reference Association","Specialization"},0)), _xlfn.XLOOKUP(_xlpm.h,Class!E:E,Class!K:K,""), _xlfn.XLOOKUP(_xlpm.f,Property!F:F,Property!K:K,"") ) ) ) -> bus
A36: 35 | B36: 2 | C36: Attribute | E36: Address | F36: Building Number | G36: String | I36: 0..1 | J36: Building Number | K36: bus | L36: =_xlfn.LET( _xlpm.c,C36,_xlpm.e,E36,_xlpm.f,F36,_xlpm.h,H36, IF( ISNUMBER(MATCH(_xlpm.c,{"Abstract Class","Class"},0)), _xlfn.XLOOKUP(_xlpm.e,Class!E:E,Class!K:K,""), IF(ISNUMBER(MATCH(_xlpm.c,{"Composition","Reference Association","Specialization"},0)), _xlfn.XLOOKUP(_xlpm.h,Class!E:E,Class!K:K,""), _xlfn.XLOOKUP(_xlpm.f,Property!F:F,Property!K:K,"") ) ) ) -> bus
A37: 36 | B37: 2 | C37: Attribute | E37: Address | F37: Street | G37: String | I37: 0..1 | J37: Street address | K37: bus | L37: =_xlfn.LET( _xlpm.c,C37,_xlpm.e,E37,_xlpm.f,F37,_xlpm.h,H37, IF( ISNUMBER(MATCH(_xlpm.c,{"Abstract Class","Class"},0)), _xlfn.XLOOKUP(_xlpm.e,Class!E:E,Class!K:K,""), IF(ISNUMBER(MATCH(_xlpm.c,{"Composition","Reference Association","Specialization"},0)), _xlfn.XLOOKUP(_xlpm.h,Class!E:E,Class!K:K,""), _xlfn.XLOOKUP(_xlpm.f,Property!F:F,Property!K:K,"") ) ) ) -> bus
A38: 37 | B38: 2 | C38: Attribute | E38: Address | F38: Address Detail | G38: String | I38: 0..1 | J38: Address Detail | K38: bus | L38: =_xlfn.LET( _xlpm.c,C38,_xlpm.e,E38,_xlpm.f,F38,_xlpm.h,H38, IF( ISNUMBER(MATCH(_xlpm.c,{"Abstract Class","Class"},0)), _xlfn.XLOOKUP(_xlpm.e,Class!E:E,Class!K:K,""), IF(ISNUMBER(MATCH(_xlpm.c,{"Composition","Reference Association","Specialization"},0)), _xlfn.XLOOKUP(_xlpm.h,Class!E:E,Class!K:K,""), _xlfn.XLOOKUP(_xlpm.f,Property!F:F,Property!K:K,"") ) ) ) -> bus
A39: 38 | B39: 2 | C39: Attribute | E39: Address | F39: City | G39: String | I39: 0..1 | J39: City | K39: bus | L39: =_xlfn.LET( _xlpm.c,C39,_xlpm.e,E39,_xlpm.f,F39,_xlpm.h,H39, IF( ISNUMBER(MATCH(_xlpm.c,{"Abstract Class","Class"},0)), _xlfn.XLOOKUP(_xlpm.e,Class!E:E,Class!K:K,""), IF(ISNUMBER(MATCH(_xlpm.c,{"Composition","Reference Association","Specialization"},0)), _xlfn.XLOOKUP(_xlpm.h,Class!E:E,Class!K:K,""), _xlfn.XLOOKUP(_xlpm.f,Property!F:F,Property!K:K,"") ) ) ) -> bus
A40: 39 | B40: 2 | C40: Attribute | E40: Address | F40: State or Province | G40: String | I40: 0..1 | J40: State, province or region | K40: bus | L40: =_xlfn.LET( _xlpm.c,C40,_xlpm.e,E40,_xlpm.f,F40,_xlpm.h,H40, IF( ISNUMBER(MATCH(_xlpm.c,{"Abstract Class","Class"},0)), _xlfn.XLOOKUP(_xlpm.e,Class!E:E,Class!K:K,""), IF(ISNUMBER(MATCH(_xlpm.c,{"Composition","Reference Association","Specialization"},0)), _xlfn.XLOOKUP(_xlpm.h,Class!E:E,Class!K:K,""), _xlfn.XLOOKUP(_xlpm.f,Property!F:F,Property!K:K,"") ) ) ) -> bus
...

Sheet FSM_btx
A1: seq | B1: level | C1: Property type | D1: Identifier | E1: Class | F1: Property Term | G1: BaseType | H1: Associated Class | I1: Multiplicity | J1: Definition
A2: 1 | B2: 1 | C2: Class | E2: Amount Structure | I2: 0..* | J2: Structure combining a monetary amount with its currency and currency role information. | K2: btx | L2: =_xlfn.LET( _xlpm.c,C2,_xlpm.e,E2,_xlpm.f,F2,_xlpm.h,H2, IF( ISNUMBER(MATCH(_xlpm.c,{"Abstract Class","Class"},0)), _xlfn.XLOOKUP(_xlpm.e,Class!E:E,Class!K:K,""), IF(ISNUMBER(MATCH(_xlpm.c,{"Composition","Reference Association","Specialization"},0)), _xlfn.XLOOKUP(_xlpm.h,Class!E:E,Class!K:K,""), _xlfn.XLOOKUP(_xlpm.f,Property!F:F,Property!K:K,"") ) ) ) -> btx
A3: 2 | B3: 2 | C3: Attribute | E3: Amount Structure | F3: Amount | G3: Monetary | I3: 1 | J3: Numeric value of the monetary amount expressed in the specified currency. | K3: btx | L3: =_xlfn.LET( _xlpm.c,C3,_xlpm.e,E3,_xlpm.f,F3,_xlpm.h,H3, IF( ISNUMBER(MATCH(_xlpm.c,{"Abstract Class","Class"},0)), _xlfn.XLOOKUP(_xlpm.e,Class!E:E,Class!K:K,""), IF(ISNUMBER(MATCH(_xlpm.c,{"Composition","Reference Association","Specialization"},0)), _xlfn.XLOOKUP(_xlpm.h,Class!E:E,Class!K:K,""), _xlfn.XLOOKUP(_xlpm.f,Property!F:F,Property!K:K,"") ) ) ) -> btx
A4: 3 | B4: 2 | C4: Attribute | E4: Amount Structure | F4: Amount Type | G4: Token | I4: 0..1 | J4: Code or text specifying the type or role of the amount, such as tax amount, tax base amount, allowance amount, or charge amount. | K4: btx | L4: =_xlfn.LET( _xlpm.c,C4,_xlpm.e,E4,_xlpm.f,F4,_xlpm.h,H4, IF( ISNUMBER(MATCH(_xlpm.c,{"Abstract Class","Class"},0)), _xlfn.XLOOKUP(_xlpm.e,Class!E:E,Class!K:K,""), IF(ISNUMBER(MATCH(_xlpm.c,{"Composition","Reference Association","Specialization"},0)), _xlfn.XLOOKUP(_xlpm.h,Class!E:E,Class!K:K,""), _xlfn.XLOOKUP(_xlpm.f,Property!F:F,Property!K:K,"") ) ) ) -> btx
A5: 4 | B5: 2 | C5: Attribute | E5: Amount Structure | F5: Currency Code | G5: Token | I5: 0..1 | J5: Code specifying the currency in which the amount is expressed, typically an ISO 4217 currency code. | K5: btx | L5: =_xlfn.LET( _xlpm.c,C5,_xlpm.e,E5,_xlpm.f,F5,_xlpm.h,H5, IF( ISNUMBER(MATCH(_xlpm.c,{"Abstract Class","Class"},0)), _xlfn.XLOOKUP(_xlpm.e,Class!E:E,Class!K:K,""), IF(ISNUMBER(MATCH(_xlpm.c,{"Composition","Reference Association","Specialization"},0)), _xlfn.XLOOKUP(_xlpm.h,Class!E:E,Class!K:K,""), _xlfn.XLOOKUP(_xlpm.f,Property!F:F,Property!K:K,"") ) ) ) -> btx
A6: 5 | B6: 2 | C6: Attribute | E6: Amount Structure | F6: Currency Code Type | G6: Token | I6: 0..1 | J6: Code specifying the role of the currency used for the amount, such as functional currency, local currency, reporting currency, or transaction currency. | K6: btx | L6: =_xlfn.LET( _xlpm.c,C6,_xlpm.e,E6,_xlpm.f,F6,_xlpm.h,H6, IF( ISNUMBER(MATCH(_xlpm.c,{"Abstract Class","Class"},0)), _xlfn.XLOOKUP(_xlpm.e,Class!E:E,Class!K:K,""), IF(ISNUMBER(MATCH(_xlpm.c,{"Composition","Reference Association","Specialization"},0)), _xlfn.XLOOKUP(_xlpm.h,Class!E:E,Class!K:K,""), _xlfn.XLOOKUP(_xlpm.f,Property!F:F,Property!K:K,"") ) ) ) -> btx
A7: 6 | B7: 1 | C7: Class | E7: Header_ Amount Structure | I7: 0..* | J7: Structure representing monetary amounts and currency information applicable to the document as a whole, such as document-level totals or aggregated tax amounts. | K7: btx | L7: =_xlfn.LET( _xlpm.c,C7,_xlpm.e,E7,_xlpm.f,F7,_xlpm.h,H7, IF( ISNUMBER(MATCH(_xlpm.c,{"Abstract Class","Class"},0)), _xlfn.XLOOKUP(_xlpm.e,Class!E:E,Class!K:K,""), IF(ISNUMBER(MATCH(_xlpm.c,{"Composition","Reference Association","Specialization"},0)), _xlfn.XLOOKUP(_xlpm.h,Class!E:E,Class!K:K,""), _xlfn.XLOOKUP(_xlpm.f,Property!F:F,Property!K:K,"") ) ) ) -> btx
A8: 7 | B8: 2 | C8: Specialization | E8: Header_ Amount Structure | H8: Amount Structure | I8: 1 | K8: btx | L8: =_xlfn.LET( _xlpm.c,C8,_xlpm.e,E8,_xlpm.f,F8,_xlpm.h,H8, IF( ISNUMBER(MATCH(_xlpm.c,{"Abstract Class","Class"},0)), _xlfn.XLOOKUP(_xlpm.e,Class!E:E,Class!K:K,""), IF(ISNUMBER(MATCH(_xlpm.c,{"Composition","Reference Association","Specialization"},0)), _xlfn.XLOOKUP(_xlpm.h,Class!E:E,Class!K:K,""), _xlfn.XLOOKUP(_xlpm.f,Property!F:F,Property!K:K,"") ) ) ) -> btx
A9: 8 | B9: 2 | C9: Attribute | E9: Header_ Amount Structure | F9: Header_ Amount | G9: Monetary | I9: 1 | J9: Numeric value of the monetary amount expressed in the specified currency. | K9: btx | L9: =_xlfn.LET( _xlpm.c,C9,_xlpm.e,E9,_xlpm.f,F9,_xlpm.h,H9, IF( ISNUMBER(MATCH(_xlpm.c,{"Abstract Class","Class"},0)), _xlfn.XLOOKUP(_xlpm.e,Class!E:E,Class!K:K,""), IF(ISNUMBER(MATCH(_xlpm.c,{"Composition","Reference Association","Specialization"},0)), _xlfn.XLOOKUP(_xlpm.h,Class!E:E,Class!K:K,""), _xlfn.XLOOKUP(_xlpm.f,Property!F:F,Property!K:K,"") ) ) ) -> btx
A10: 9 | B10: 2 | C10: Attribute | E10: Header_ Amount Structure | F10: Header_ Amount Type | G10: String | I10: 0..1 | J10: Code or text specifying the type or role of the amount, such as tax amount, tax base amount, allowance amount, or charge amount. | K10: btx | L10: =_xlfn.LET( _xlpm.c,C10,_xlpm.e,E10,_xlpm.f,F10,_xlpm.h,H10, IF( ISNUMBER(MATCH(_xlpm.c,{"Abstract Class","Class"},0)), _xlfn.XLOOKUP(_xlpm.e,Class!E:E,Class!K:K,""), IF(ISNUMBER(MATCH(_xlpm.c,{"Composition","Reference Association","Specialization"},0)), _xlfn.XLOOKUP(_xlpm.h,Class!E:E,Class!K:K,""), _xlfn.XLOOKUP(_xlpm.f,Property!F:F,Property!K:K,"") ) ) ) -> btx
A11: 10 | B11: 2 | C11: Attribute | E11: Header_ Amount Structure | F11: Header_ Currency Code | G11: Token | I11: 0..1 | J11: Code specifying the currency in which the amount is expressed, typically an ISO 4217 currency code. | K11: btx | L11: =_xlfn.LET( _xlpm.c,C11,_xlpm.e,E11,_xlpm.f,F11,_xlpm.h,H11, IF( ISNUMBER(MATCH(_xlpm.c,{"Abstract Class","Class"},0)), _xlfn.XLOOKUP(_xlpm.e,Class!E:E,Class!K:K,""), IF(ISNUMBER(MATCH(_xlpm.c,{"Composition","Reference Association","Specialization"},0)), _xlfn.XLOOKUP(_xlpm.h,Class!E:E,Class!K:K,""), _xlfn.XLOOKUP(_xlpm.f,Property!F:F,Property!K:K,"") ) ) ) -> btx
A12: 11 | B12: 2 | C12: Attribute | E12: Header_ Amount Structure | F12: Header_ Currency Code Type | G12: Token | I12: 0..1 | J12: Code specifying the role of the currency used for the amount, such as functional currency, local currency, reporting currency, or transaction currency. | K12: btx | L12: =_xlfn.LET( _xlpm.c,C12,_xlpm.e,E12,_xlpm.f,F12,_xlpm.h,H12, IF( ISNUMBER(MATCH(_xlpm.c,{"Abstract Class","Class"},0)), _xlfn.XLOOKUP(_xlpm.e,Class!E:E,Class!K:K,""), IF(ISNUMBER(MATCH(_xlpm.c,{"Composition","Reference Association","Specialization"},0)), _xlfn.XLOOKUP(_xlpm.h,Class!E:E,Class!K:K,""), _xlfn.XLOOKUP(_xlpm.f,Property!F:F,Property!K:K,"") ) ) ) -> btx
A13: 12 | B13: 1 | C13: Class | E13: Detail_ Amount Structure | I13: 0..* | J13: Structure representing monetary amounts and currency information applicable to an individual line, such as line-level net amounts, tax calculation bases, allowances, or charges. | K13: btx | L13: =_xlfn.LET( _xlpm.c,C13,_xlpm.e,E13,_xlpm.f,F13,_xlpm.h,H13, IF( ISNUMBER(MATCH(_xlpm.c,{"Abstract Class","Class"},0)), _xlfn.XLOOKUP(_xlpm.e,Class!E:E,Class!K:K,""), IF(ISNUMBER(MATCH(_xlpm.c,{"Composition","Reference Association","Specialization"},0)), _xlfn.XLOOKUP(_xlpm.h,Class!E:E,Class!K:K,""), _xlfn.XLOOKUP(_xlpm.f,Property!F:F,Property!K:K,"") ) ) ) -> btx
A14: 13 | B14: 2 | C14: Specialization | E14: Detail_ Amount Structure | H14: Amount Structure | I14: 1 | K14: btx | L14: =_xlfn.LET( _xlpm.c,C14,_xlpm.e,E14,_xlpm.f,F14,_xlpm.h,H14, IF( ISNUMBER(MATCH(_xlpm.c,{"Abstract Class","Class"},0)), _xlfn.XLOOKUP(_xlpm.e,Class!E:E,Class!K:K,""), IF(ISNUMBER(MATCH(_xlpm.c,{"Composition","Reference Association","Specialization"},0)), _xlfn.XLOOKUP(_xlpm.h,Class!E:E,Class!K:K,""), _xlfn.XLOOKUP(_xlpm.f,Property!F:F,Property!K:K,"") ) ) ) -> btx
A15: 14 | B15: 2 | C15: Attribute | E15: Detail_ Amount Structure | F15: Detail_ Amount | G15: Monetary | I15: 1 | J15: Numeric value of the monetary amount expressed in the specified currency. | K15: btx | L15: =_xlfn.LET( _xlpm.c,C15,_xlpm.e,E15,_xlpm.f,F15,_xlpm.h,H15, IF( ISNUMBER(MATCH(_xlpm.c,{"Abstract Class","Class"},0)), _xlfn.XLOOKUP(_xlpm.e,Class!E:E,Class!K:K,""), IF(ISNUMBER(MATCH(_xlpm.c,{"Composition","Reference Association","Specialization"},0)), _xlfn.XLOOKUP(_xlpm.h,Class!E:E,Class!K:K,""), _xlfn.XLOOKUP(_xlpm.f,Property!F:F,Property!K:K,"") ) ) ) -> btx
A16: 15 | B16: 2 | C16: Attribute | E16: Detail_ Amount Structure | F16: Detail_ Amount Type | G16: String | I16: 0..1 | J16: Code or text specifying the type or role of the amount, such as tax amount, tax base amount, allowance amount, or charge amount. | K16: btx | L16: =_xlfn.LET( _xlpm.c,C16,_xlpm.e,E16,_xlpm.f,F16,_xlpm.h,H16, IF( ISNUMBER(MATCH(_xlpm.c,{"Abstract Class","Class"},0)), _xlfn.XLOOKUP(_xlpm.e,Class!E:E,Class!K:K,""), IF(ISNUMBER(MATCH(_xlpm.c,{"Composition","Reference Association","Specialization"},0)), _xlfn.XLOOKUP(_xlpm.h,Class!E:E,Class!K:K,""), _xlfn.XLOOKUP(_xlpm.f,Property!F:F,Property!K:K,"") ) ) ) -> btx
A17: 16 | B17: 2 | C17: Attribute | E17: Detail_ Amount Structure | F17: Detail_ Currency Code | G17: Token | I17: 0..1 | J17: Code specifying the currency in which the amount is expressed, typically an ISO 4217 currency code. | K17: btx | L17: =_xlfn.LET( _xlpm.c,C17,_xlpm.e,E17,_xlpm.f,F17,_xlpm.h,H17, IF( ISNUMBER(MATCH(_xlpm.c,{"Abstract Class","Class"},0)), _xlfn.XLOOKUP(_xlpm.e,Class!E:E,Class!K:K,""), IF(ISNUMBER(MATCH(_xlpm.c,{"Composition","Reference Association","Specialization"},0)), _xlfn.XLOOKUP(_xlpm.h,Class!E:E,Class!K:K,""), _xlfn.XLOOKUP(_xlpm.f,Property!F:F,Property!K:K,"") ) ) ) -> btx
A18: 17 | B18: 2 | C18: Attribute | E18: Detail_ Amount Structure | F18: Detail_ Currency Code Type | G18: Token | I18: 0..1 | J18: Code specifying the role of the currency used for the amount, such as functional currency, local currency, reporting currency, or transaction currency. | K18: btx | L18: =_xlfn.LET( _xlpm.c,C18,_xlpm.e,E18,_xlpm.f,F18,_xlpm.h,H18, IF( ISNUMBER(MATCH(_xlpm.c,{"Abstract Class","Class"},0)), _xlfn.XLOOKUP(_xlpm.e,Class!E:E,Class!K:K,""), IF(ISNUMBER(MATCH(_xlpm.c,{"Composition","Reference Association","Specialization"},0)), _xlfn.XLOOKUP(_xlpm.h,Class!E:E,Class!K:K,""), _xlfn.XLOOKUP(_xlpm.f,Property!F:F,Property!K:K,"") ) ) ) -> btx
A19: 18 | B19: 2 | C19: Attribute | E19: Detail_ Amount Structure | F19: Detail Adjustment Reason Description Code | G19: Code | I19: 0..1 | J19: UNTDED 4465 Adjustment reason description code. Code specifying the reason for an adjustment. | K19: btx | L19: =_xlfn.LET( _xlpm.c,C19,_xlpm.e,E19,_xlpm.f,F19,_xlpm.h,H19, IF( ISNUMBER(MATCH(_xlpm.c,{"Abstract Class","Class"},0)), _xlfn.XLOOKUP(_xlpm.e,Class!E:E,Class!K:K,""), IF(ISNUMBER(MATCH(_xlpm.c,{"Composition","Reference Association","Specialization"},0)), _xlfn.XLOOKUP(_xlpm.h,Class!E:E,Class!K:K,""), _xlfn.XLOOKUP(_xlpm.f,Property!F:F,Property!K:K,"") ) ) ) -> btx
A20: 19 | B20: 1 | C20: Class | E20: Detail_ Multicurrency | I20: 0..* | J20: Class to provide additional information related to home currencies that differ from original currencies applied at the transaction detail (line) level and related exchange rates - typically this will be used to record exchange rates and amounts in currencies and/or on dates other than those of the original transaction. This class allows recording of exchange rates using a third currency as a triangulation currency. This is often EUR but is not restricted to being so. This class may be repeated as many times as necessary to record amounts in foreign currencies on the same or different dates. | K20: muc | L20: =_xlfn.LET( _xlpm.c,C20,_xlpm.e,E20,_xlpm.f,F20,_xlpm.h,H20, IF( ISNUMBER(MATCH(_xlpm.c,{"Abstract Class","Class"},0)), _xlfn.XLOOKUP(_xlpm.e,Class!E:E,Class!K:K,""), IF(ISNUMBER(MATCH(_xlpm.c,{"Composition","Reference Association","Specialization"},0)), _xlfn.XLOOKUP(_xlpm.h,Class!E:E,Class!K:K,""), _xlfn.XLOOKUP(_xlpm.f,Property!F:F,Property!K:K,"") ) ) ) -> muc
A21: 20 | B21: 2 | C21: Specialization | E21: Detail_ Multicurrency | H21: Multicurrency | I21: 1 | K21: muc | L21: =_xlfn.LET( _xlpm.c,C21,_xlpm.e,E21,_xlpm.f,F21,_xlpm.h,H21, IF( ISNUMBER(MATCH(_xlpm.c,{"Abstract Class","Class"},0)), _xlfn.XLOOKUP(_xlpm.e,Class!E:E,Class!K:K,""), IF(ISNUMBER(MATCH(_xlpm.c,{"Composition","Reference Association","Specialization"},0)), _xlfn.XLOOKUP(_xlpm.h,Class!E:E,Class!K:K,""), _xlfn.XLOOKUP(_xlpm.f,Property!F:F,Property!K:K,"") ) ) ) -> muc
A22: 21 | B22: 2 | C22: Attribute | E22: Detail_ Multicurrency | F22: Detail_ Multicurrency Exchange Rate Date | G22: Date Time | I22: 0..1 | J22: Date of exchange rate (other than original transaction date) on which amount is expressed as amountRestatedAmount or amountTriangulationAmount | K22: muc | L22: =_xlfn.LET( _xlpm.c,C22,_xlpm.e,E22,_xlpm.f,F22,_xlpm.h,H22, IF( ISNUMBER(MATCH(_xlpm.c,{"Abstract Class","Class"},0)), _xlfn.XLOOKUP(_xlpm.e,Class!E:E,Class!K:K,""), IF(ISNUMBER(MATCH(_xlpm.c,{"Composition","Reference Association","Specialization"},0)), _xlfn.XLOOKUP(_xlpm.h,Class!E:E,Class!K:K,""), _xlfn.XLOOKUP(_xlpm.f,Property!F:F,Property!K:K,"") ) ) ) -> muc
A23: 22 | B23: 2 | C23: Attribute | E23: Detail_ Multicurrency | F23: Detail_ Multicurrency Foreign Currency Amount | G23: Monetary | I23: 0..1 | J23: The amount in the foreign currency identified by amountRestatedCurrency as of multicurrencyDetailExchangeRateDate. | K23: muc | L23: =_xlfn.LET( _xlpm.c,C23,_xlpm.e,E23,_xlpm.f,F23,_xlpm.h,H23, IF( ISNUMBER(MATCH(_xlpm.c,{"Abstract Class","Class"},0)), _xlfn.XLOOKUP(_xlpm.e,Class!E:E,Class!K:K,""), IF(ISNUMBER(MATCH(_xlpm.c,{"Composition","Reference Association","Specialization"},0)), _xlfn.XLOOKUP(_xlpm.h,Class!E:E,Class!K:K,""), _xlfn.XLOOKUP(_xlpm.f,Property!F:F,Property!K:K,"") ) ) ) -> muc
A24: 23 | B24: 2 | C24: Attribute | E24: Detail_ Multicurrency | F24: Detail_ Multicurrency Foreign Currency | G24: QName | I24: 0..1 | J24: The currency in which amountRestatedAmount is expressed. Recommended ISO 4217 coding. | K24: muc | L24: =_xlfn.LET( _xlpm.c,C24,_xlpm.e,E24,_xlpm.f,F24,_xlpm.h,H24, IF( ISNUMBER(MATCH(_xlpm.c,{"Abstract Class","Class"},0)), _xlfn.XLOOKUP(_xlpm.e,Class!E:E,Class!K:K,""), IF(ISNUMBER(MATCH(_xlpm.c,{"Composition","Reference Association","Specialization"},0)), _xlfn.XLOOKUP(_xlpm.h,Class!E:E,Class!K:K,""), _xlfn.XLOOKUP(_xlpm.f,Property!F:F,Property!K:K,"") ) ) ) -> muc
A25: 24 | B25: 2 | C25: Attribute | E25: Detail_ Multicurrency | F25: Detail_ Multicurrency Exchange Rate | G25: Pure | I25: 0..1 | J25: Exchange rate used to convert amountRestatedAmount as of multicurrencyDetailExchangeRateDate (expressed as national currency divided by foreign currency) | K25: muc | L25: =_xlfn.LET( _xlpm.c,C25,_xlpm.e,E25,_xlpm.f,F25,_xlpm.h,H25, IF( ISNUMBER(MATCH(_xlpm.c,{"Abstract Class","Class"},0)), _xlfn.XLOOKUP(_xlpm.e,Class!E:E,Class!K:K,""), IF(ISNUMBER(MATCH(_xlpm.c,{"Composition","Reference Association","Specialization"},0)), _xlfn.XLOOKUP(_xlpm.h,Class!E:E,Class!K:K,""), _xlfn.XLOOKUP(_xlpm.f,Property!F:F,Property!K:K,"") ) ) ) -> muc
A26: 25 | B26: 2 | C26: Attribute | E26: Detail_ Multicurrency | F26: Detail_ Multicurrency Exchange Rate Source | G26: String | I26: 0..1 | J26: Source of Exchange Rate for restated amount - for example, Reuters, Bloomberg | K26: muc | L26: =_xlfn.LET( _xlpm.c,C26,_xlpm.e,E26,_xlpm.f,F26,_xlpm.h,H26, IF( ISNUMBER(MATCH(_xlpm.c,{"Abstract Class","Class"},0)), _xlfn.XLOOKUP(_xlpm.e,Class!E:E,Class!K:K,""), IF(ISNUMBER(MATCH(_xlpm.c,{"Composition","Reference Association","Specialization"},0)), _xlfn.XLOOKUP(_xlpm.h,Class!E:E,Class!K:K,""), _xlfn.XLOOKUP(_xlpm.f,Property!F:F,Property!K:K,"") ) ) ) -> muc
A27: 26 | B27: 2 | C27: Attribute | E27: Detail_ Multicurrency | F27: Detail_ Multicurrency Exchange Rate Type | G27: String | I27: 0..1 | J27: Type of Exchange Rate for restated amount - for example, spot rate, forward contract etc. | K27: muc | L27: =_xlfn.LET( _xlpm.c,C27,_xlpm.e,E27,_xlpm.f,F27,_xlpm.h,H27, IF( ISNUMBER(MATCH(_xlpm.c,{"Abstract Class","Class"},0)), _xlfn.XLOOKUP(_xlpm.e,Class!E:E,Class!K:K,""), IF(ISNUMBER(MATCH(_xlpm.c,{"Composition","Reference Association","Specialization"},0)), _xlfn.XLOOKUP(_xlpm.h,Class!E:E,Class!K:K,""), _xlfn.XLOOKUP(_xlpm.f,Property!F:F,Property!K:K,"") ) ) ) -> muc
A28: 27 | B28: 2 | C28: Attribute | E28: Detail_ Multicurrency | F28: Detail_ Multicurrency Comment | G28: String | I28: 0..1 | J28: Comment describing the enclosing multicurrencyDetail class's contents. May include reason for recording additional exchange rates other than that used at the time of the original transaction. | K28: muc | L28: =_xlfn.LET( _xlpm.c,C28,_xlpm.e,E28,_xlpm.f,F28,_xlpm.h,H28, IF( ISNUMBER(MATCH(_xlpm.c,{"Abstract Class","Class"},0)), _xlfn.XLOOKUP(_xlpm.e,Class!E:E,Class!K:K,""), IF(ISNUMBER(MATCH(_xlpm.c,{"Composition","Reference Association","Specialization"},0)), _xlfn.XLOOKUP(_xlpm.h,Class!E:E,Class!K:K,""), _xlfn.XLOOKUP(_xlpm.f,Property!F:F,Property!K:K,"") ) ) ) -> muc
